Workbook
Name espécies_invertebrados: 'DADOS INVERTEBRADOS'!$T$2:$T$51
Name espécies_peixes: 'DADOS PEIXES'!$AA$2:$AA$161
Name indicadores_invertebrados: 'DADOS INVERTEBRADOS'!$S$3:$S$17
Name indicadores_peixes: 'DADOS PEIXES'!$Z$3:$Z$18

Sheet INSTRUÇÕES
A2: Para que os dados coletados por uma equipe sejam incorporados ao banco de dados do Reef Check Brasil, e sejam utilizados em relatórios e publicações sobre o estado dos ambientes recifais na costa brasileira, foram adaptadas planilhas excel para os diferentes tipos de indicadores amostrados pelo Reef Check Brasil
A3: COMO USAR AS PLANILHAS EXCEL
A5: 1. Insira os dados de peixes e invertebrados, registrados durante os censos, nas células em branco das folhas DADOS PEIXES e DADOS INVERTEBRADOS. Para cada transecto (A, B, C e D) deverão ser preenchidas as colunas Indicadores,Espécie e Número,e para os peixes ainda a coluna Comprimento (rotina avançada).
A7: 2. Os dados deverão ser inseridos nas caixas em branco e, para facilitar a sua entrada, foram criadas listas de indicadores e espécies, nas quais é apenas necessário selecionar a opção desejada. Novas ocorrências deverão ser preenchidas como “novo registro” e mencionadas no campo Observações ao final da folha.
A9: 3. No caso dos peixes (DADOS PEIXES), existem duas formas de preencher a folha de dados, conforme a rotina realizada durante os censos. Para a rotina mais simples, somente com a contagem de espécies dentro das categorias, deverá ser apenas indicada a categoria, a espécie e número de peixes correspondente a essa categoria. Para a rotina avançada, além da categoria, espécie e número, são também incluídos dados sobre o comprimento (em centímetros) dos indivíduos. Assim, cada linha deverá corresponder a todos os indivíduos da mesma espécie e com o mesmo comprimento estimado, podendo para cada categoria e espécie haver várias linhas para os diferentes tamanhos estimados nos censos. No caso de cardumes de peixe com diferentes tamanhos, dificultando uma identificação muito detalhada, peixes de tamanhos diferentes podem ser agrupados e usado o comprimento médio do cardume na coluna Comprimento.
A11: 4. Para os invertebrados (DADOS INVERTEBRADOS), preencha com o número de animais contados, os impactos encontrados e as estimativas de coral nas respectivas caixas. Lembre-se de colocar ZERO quando nada foi registrado. Não ver nada é informação importante. Se uma caixa estiver em branco, será assumido que não se estava procurando por aquele animal ou impacto.
A13: 5. Por favor confirme se todos os dados foram inseridos corretamente na planilha.
A16: COMO ANALISAR OS DADOS
A18: 1. Ao inserir os dados, os gráficos são produzidos em simultâneo e automaticamente na folha GRÁFICOS.
A20: 2. Somente deverá ser preenchido o nome do sítio monitorado, a data e a profundidade dos transectos substituindo as palavras em azul no título do gráfico. Depois o texto deverá ser alterado para preto selecionando o botão de cor de texto na barra de ferramentas da fonte.
A22: 3. A página estará pronta para imprimir, e os gráficos desejados poderão ser selecionados e copiados em um documento Word.
A25: COMO ENVIAR OS DADOS
... A54: Para estatística geral "Experimental Design and Data Analysis for Biologists", por G. P. Quinn e M. J. Keough, 2002, Cambridge University Press.

Sheet SUMÁRIO
B3: Sítio: | C3: Taquaruçu | G3: Região: | H3: Recife de For a - Porto Seguro
B4: Profundidade: | C4: 2 | G4: Data: | H4: 43516
B5: Líder da equipe: | C5: Fábio Negrão | G5: Horário (inicial e final): | H5: 07:50:00-11:40
B9: Dados registrados por (nome completo): | C9: Edmilson Do Carmo
B11: PEIXES | C11: A | D11: B | E11: C | F11: D | G11: Total | H11: Média | I11: DP
B12: Borboletas (Chaetodontidae) | C12: =SUMIF('DADOS PEIXES'!$F$16:$F$65, "Borboletas", 'DADOS PEIXES'!$I$16:$I$65) -> 5 | D12: =SUMIF('DADOS PEIXES'!$J$16:$J$65, "Borboletas", 'DADOS PEIXES'!$M$16:$M$65) -> 20 | E12: =SUMIF('DADOS PEIXES'!$P$16:$P$65, "Borboletas", 'DADOS PEIXES'!$S$16:$S$65) -> 15 | F12: =SUMIF('DADOS PEIXES'!$T$16:$T$65, "Borboletas", 'DADOS PEIXES'!$W$16:$W$65) -> 0 | G12: =SUM(C12:D12:E12:F12) -> 40 | H12: =AVERAGE(C12:D12:E12:F12) -> 10 | I12: =STDEV(C12:D12:E12:F12) -> 9.1287093
B13: Cirurgiões > 20 cm (Acanthuridae) | C13: =SUMIF('DADOS PEIXES'!$F$16:$F$65, "Cirurgiões > 20 cm", 'DADOS PEIXES'!$I$16:$I$65) -> 0 | D13: =SUMIF('DADOS PEIXES'!$J$16:$J$65, "Cirurgiões > 20 cm", 'DADOS PEIXES'!$M$16:$M$65) -> 0 | E13: =SUMIF('DADOS PEIXES'!$P$16:$P$65, "Cirurgiões > 20 cm", 'DADOS PEIXES'!$S$16:$S$65) -> 0 | F13: =SUMIF('DADOS PEIXES'!$T$16:$T$65, "Cirurgiões > 20 cm", 'DADOS PEIXES'!$W$16:$W$65) -> 0 | G13: =SUM(C13:D13:E13:F13) -> 0 | H13: =AVERAGE(C13:D13:E13:F13) -> 0 | I13: =STDEV(C13:D13:E13:F13) -> 0
B14: Cirurgiões ≤ 20 cm (Acanthuridae) | C14: =SUMIF('DADOS PEIXES'!$F$16:$F$65, "Cirurgiões ≤ 20 cm", 'DADOS PEIXES'!$I$16:$I$65) -> 3 | D14: =SUMIF('DADOS PEIXES'!$J$16:$J$65, "Cirurgiões ≤ 20 cm", 'DADOS PEIXES'!$M$16:$M$65) -> 13 | E14: =SUMIF('DADOS PEIXES'!$P$16:$P$65, "Cirurgiões ≤ 20 cm", 'DADOS PEIXES'!$S$16:$S$65) -> 54 | F14: =SUMIF('DADOS PEIXES'!$T$16:$T$65, "Cirurgiões ≤ 20 cm", 'DADOS PEIXES'!$W$16:$W$65) -> 0 | G14: =SUM(C14:D14:E14:F14) -> 70 | H14: =AVERAGE(C14:D14:E14:F14) -> 17.5 | I14: =STDEV(C14:D14:E14:F14) -> 24.959968
B15: Garoupas > 30 cm (Epinephelidae) | C15: =SUMIF('DADOS PEIXES'!$F$16:$F$65, "Garoupas > 30cm", 'DADOS PEIXES'!$I$16:$I$65) -> 0 | D15: =SUMIF('DADOS PEIXES'!$J$16:$J$65, "Garoupas > 30cm", 'DADOS PEIXES'!$M$16:$M$65) -> 0 | E15: =SUMIF('DADOS PEIXES'!$P$16:$P$65, "Garoupas > 30cm", 'DADOS PEIXES'!$S$16:$S$65) -> 0 | F15: =SUMIF('DADOS PEIXES'!$T$16:$T$65, "Garoupas > 30cm", 'DADOS PEIXES'!$W$16:$W$65) -> 0 | G15: =SUM(C15:D15:E15:F15) -> 0 | H15: =AVERAGE(C15:D15:E15:F15) -> 0 | I15: =STDEV(C15:D15:E15:F15) -> 0
B16: Garoupas ≤ 30 cm (Epinephelidae) | C16: =SUMIF('DADOS PEIXES'!$F$16:$F$65, "Garoupas ≤ 30cm", 'DADOS PEIXES'!$I$16:$I$65) -> 0 | D16: =SUMIF('DADOS PEIXES'!$J$16:$J$65, "Garoupas ≤ 30cm", 'DADOS PEIXES'!$M$16:$M$65) -> 0 | E16: =SUMIF('DADOS PEIXES'!$P$16:$P$65, "Garoupas ≤ 30cm", 'DADOS PEIXES'!$S$16:$S$65) -> 1 | F16: =SUMIF('DADOS PEIXES'!$T$16:$T$65, "Garoupas ≤ 30cm", 'DADOS PEIXES'!$W$16:$W$65) -> 0 | G16: =SUM(C16:D16:E16:F16) -> 1 | H16: =AVERAGE(C16:D16:E16:F16) -> 0.25 | I16: =STDEV(C16:D16:E16:F16) -> 0.5
B17: Mero (E. itajara) | C17: =SUMIF('DADOS PEIXES'!$F$16:$F$65, "Mero", 'DADOS PEIXES'!$I$16:$I$65) -> 0 | D17: =SUMIF('DADOS PEIXES'!$J$16:$J$65, "Mero", 'DADOS PEIXES'!$M$16:$M$65) -> 0 | E17: =SUMIF('DADOS PEIXES'!$P$16:$P$65, "Mero", 'DADOS PEIXES'!$S$16:$S$65) -> 0 | F17: =SUMIF('DADOS PEIXES'!$T$16:$T$65, "Mero", 'DADOS PEIXES'!$W$16:$W$65) -> 0 | G17: =SUM(C17:D17:E17:F17) -> 0 | H17: =AVERAGE(C17:D17:E17:F17) -> 0 | I17: =STDEV(C17:D17:E17:F17) -> 0
B18: Móreias | C18: =SUMIF('DADOS PEIXES'!$F$16:$F$65, "Moréias", 'DADOS PEIXES'!$I$16:$I$65) -> 0 | D18: =SUMIF('DADOS PEIXES'!$J$16:$J$65, "Moréias", 'DADOS PEIXES'!$M$16:$M$65) -> 0 | E18: =SUMIF('DADOS PEIXES'!$P$16:$P$65, "Moréias", 'DADOS PEIXES'!$S$16:$S$65) -> 0 | F18: =SUMIF('DADOS PEIXES'!$T$16:$T$65, "Moréias", 'DADOS PEIXES'!$W$16:$W$65) -> 0 | G18: =SUM(C18:D18:E18:F18) -> 0 | H18: =AVERAGE(C18:D18:E18:F18) -> 0 | I18: =STDEV(C18:D18:E18:F18) -> 0
B19: Ornamentais | C19: =SUMIF('DADOS PEIXES'!$F$16:$F$65, "Ornamentais", 'DADOS PEIXES'!$I$16:$I$65) -> 0 | D19: =SUMIF('DADOS PEIXES'!$J$16:$J$65, "Ornamentais", 'DADOS PEIXES'!$M$16:$M$65) -> 11 | E19: =SUMIF('DADOS PEIXES'!$P$16:$P$65, "Ornamentais", 'DADOS PEIXES'!$S$16:$S$65) -> 6 | F19: =SUMIF('DADOS PEIXES'!$T$16:$T$65, "Ornamentais", 'DADOS PEIXES'!$W$16:$W$65) -> 7 | G19: =SUM(C19:D19:E19:F19) -> 24 | H19: =AVERAGE(C19:D19:E19:F19) -> 6 | I19: =STDEV(C19:D19:E19:F19) -> 4.5460606
B20: Papagaios > 20 cm (Scarinae) | C20: =SUMIF('DADOS PEIXES'!$F$16:$F$65, "Bobós, papagaios > 20 cm", 'DADOS PEIXES'!$I$16:$I$65) -> 0 | D20: =SUMIF('DADOS PEIXES'!$J$16:$J$65, "Bobós, papagaios > 20 cm", 'DADOS PEIXES'!$M$16:$M$65) -> 0 | E20: =SUMIF('DADOS PEIXES'!$P$16:$P$65, "Bobós, papagaios > 20 cm", 'DADOS PEIXES'!$S$16:$S$65) -> 0 | F20: =SUMIF('DADOS PEIXES'!$T$16:$T$65, "Bobós, papagaios > 20 cm", 'DADOS PEIXES'!$W$16:$W$65) -> 0 | G20: =SUM(C20:D20:E20:F20) -> 0 | H20: =AVERAGE(C20:D20:E20:F20) -> 0 | I20: =STDEV(C20:D20:E20:F20) -> 0
B21: Papagaios ≤ 20 cm (Scarinae) | C21: =SUMIF('DADOS PEIXES'!$F$16:$F$65, "Bobós, papagaios ≤ 20 cm", 'DADOS PEIXES'!$I$16:$I$65) -> 0 | D21: =SUMIF('DADOS PEIXES'!$J$16:$J$65, "Bobós, papagaios ≤ 20 cm", 'DADOS PEIXES'!$M$16:$M$65) -> 8 | E21: =SUMIF('DADOS PEIXES'!$P$16:$P$65, "Bobós, papagaios ≤ 20 cm", 'DADOS PEIXES'!$S$16:$S$65) -> 0 | F21: =SUMIF('DADOS PEIXES'!$T$16:$T$65, "Bobós, papagaios ≤ 20 cm", 'DADOS PEIXES'!$W$16:$W$65) -> 0 | G21: =SUM(C21:D21:E21:F21) -> 8 | H21: =AVERAGE(C21:D21:E21:F21) -> 2 | I21: =STDEV(C21:D21:E21:F21) -> 4
B22: Raias | C22: =SUMIF('DADOS PEIXES'!$F$16:$F$65, "Raias", 'DADOS PEIXES'!$I$16:$I$65) -> 0 | D22: =SUMIF('DADOS PEIXES'!$J$16:$J$65, "Raias", 'DADOS PEIXES'!$M$16:$M$65) -> 0 | E22: =SUMIF('DADOS PEIXES'!$P$16:$P$65, "Raias", 'DADOS PEIXES'!$S$16:$S$65) -> 0 | F22: =SUMIF('DADOS PEIXES'!$T$16:$T$65, "Raias", 'DADOS PEIXES'!$W$16:$W$65) -> 0 | G22: =SUM(C22:D22:E22:F22) -> 0 | H22: =AVERAGE(C22:D22:E22:F22) -> 0 | I22: =STDEV(C22:D22:E22:F22) -> 0
B23: Tubarões | C23: =SUMIF('DADOS PEIXES'!$F$16:$F$65, "Tubarões", 'DADOS PEIXES'!$I$16:$I$65) -> 0 | D23: =SUMIF('DADOS PEIXES'!$J$16:$J$65, "Tubarões", 'DADOS PEIXES'!$M$16:$M$65) -> 1 | E23: =SUMIF('DADOS PEIXES'!$P$16:$P$65, "Tubarões", 'DADOS PEIXES'!$S$16:$S$65) -> 0 | F23: =SUMIF('DADOS PEIXES'!$T$16:$T$65, "Tubarões", 'DADOS PEIXES'!$W$16:$W$65) -> 0 | G23: =SUM(C23:D23:E23:F23) -> 1 | H23: =AVERAGE(C23:D23:E23:F23) -> 0.25 | I23: =STDEV(C23:D23:E23:F23) -> 0.5
B24: Vermelhos (Lutjanidae) | C24: =SUMIF('DADOS PEIXES'!$F$16:$F$65, "Vermelhos", 'DADOS PEIXES'!$I$16:$I$65) -> 0 | D24: =SUMIF('DADOS PEIXES'!$J$16:$J$65, "Vermelhos", 'DADOS PEIXES'!$M$16:$M$65) -> 2 | E24: =SUMIF('DADOS PEIXES'!$P$16:$P$65, "Vermelhos", 'DADOS PEIXES'!$S$16:$S$65) -> 0 | F24: =SUMIF('DADOS PEIXES'!$T$16:$T$65, "Vermelhos", 'DADOS PEIXES'!$W$16:$W$65) -> 4 | G24: =SUM(C24:D24:E24:F24) -> 6 | H24: =AVERAGE(C24:D24:E24:F24) -> 1.5 | I24: =STDEV(C24:D24:E24:F24) -> 1.9148542
B25: Xiras > 10 cm (Haemulidae) | C25: =SUMIF('DADOS PEIXES'!$F$16:$F$65, "Xiras > 10 cm", 'DADOS PEIXES'!$I$16:$I$65) -> 0 | D25: =SUMIF('DADOS PEIXES'!$J$16:$J$65, "Xiras > 10 cm", 'DADOS PEIXES'!$M$16:$M$65) -> 0 | E25: =SUMIF('DADOS PEIXES'!$P$16:$P$65, "Xiras > 10 cm", 'DADOS PEIXES'!$S$16:$S$65) -> 0 | F25: =SUMIF('DADOS PEIXES'!$T$16:$T$65, "Xiras > 10 cm", 'DADOS PEIXES'!$W$16:$W$65) -> 0 | G25: =SUM(C25:D25:E25:F25) -> 0 | H25: =AVERAGE(C25:D25:E25:F25) -> 0 | I25: =STDEV(C25:D25:E25:F25) -> 0
B26: Xiras ≤ 10 cm (Haemulidae) | C26: =SUMIF('DADOS PEIXES'!$F$16:$F$65, "Xiras ≤ 10 cm", 'DADOS PEIXES'!$I$16:$I$65) -> 14 | D26: =SUMIF('DADOS PEIXES'!$J$16:$J$65, "Xiras ≤ 10 cm", 'DADOS PEIXES'!$M$16:$M$65) -> 36 | E26: =SUMIF('DADOS PEIXES'!$P$16:$P$65, "Xiras ≤ 10 cm", 'DADOS PEIXES'!$S$16:$S$65) -> 60 | F26: =SUMIF('DADOS PEIXES'!$T$16:$T$65, "Xiras ≤ 10 cm", 'DADOS PEIXES'!$W$16:$W$65) -> 0 | G26: =SUM(C26:D26:E26:F26) -> 110 | H26: =AVERAGE(C26:D26:E26:F26) -> 27.5 | I26: =STDEV(C26:D26:E26:F26) -> 26.248809
B28: Mero | C28: A | D28: B | E28: C | F28: D | G28: Total | H28: Média | I28: DP
B29: Mero 20-30 cm | C29: =SUMIFS('DADOS PEIXES'!$I$16:$I$65, 'DADOS PEIXES'!$F$16:$F$65, "Mero", 'DADOS PEIXES'!$H$16:$H$65, ">=20", 'DADOS PEIXES'!$H$16:$H$65, "<30" ) -> 0 | D29: =SUMIFS('DADOS PEIXES'!$M$16:$M$65, 'DADOS PEIXES'!$J$16:$J$65, "Mero", 'DADOS PEIXES'!$L$16:$L$65, ">=20", 'DADOS PEIXES'!$L$16:$L$65, "<30" ) -> 0 | E29: =SUMIFS('DADOS PEIXES'!$S$16:$S$65, 'DADOS PEIXES'!$P$16:$P$65, "Mero", 'DADOS PEIXES'!$R$16:$R$65, ">20", 'DADOS PEIXES'!$R$16:$R$65, "<30" ) -> 0 | F29: =SUMIFS('DADOS PEIXES'!$W$16:$W$65, 'DADOS PEIXES'!$T$16:$T$65, "Mero", 'DADOS PEIXES'!$V$16:$V$65, ">=20", 'DADOS PEIXES'!$V$16:$V$65, "<30" ) -> 0 | G29: =SUM(C29:D29:E29:F29) -> 0 | H29: =AVERAGE(C29:D29:E29:F29) -> 0 | I29: =STDEV(C29:D29:E29:F29) -> 0
B30: Mero 30-40 cm | C30: =SUMIFS('DADOS PEIXES'!$I$16:$I$65, 'DADOS PEIXES'!$F$16:$F$65, "Mero", 'DADOS PEIXES'!$H$16:$H$65, ">=30", 'DADOS PEIXES'!$H$16:$H$65, "<40" ) -> 0 | D30: =SUMIFS('DADOS PEIXES'!$M$16:$M$65, 'DADOS PEIXES'!$J$16:$J$65, "Mero", 'DADOS PEIXES'!$L$16:$L$65, ">=30", 'DADOS PEIXES'!$L$16:$L$65, "<40" ) -> 0 | E30: =SUMIFS('DADOS PEIXES'!$S$16:$S$65, 'DADOS PEIXES'!$P$16:$P$65, "Mero", 'DADOS PEIXES'!$R$16:$R$65, ">=30", 'DADOS PEIXES'!$R$16:$R$65, "<40" ) -> 0 | F30: =SUMIFS('DADOS PEIXES'!$W$16:$W$65, 'DADOS PEIXES'!$T$16:$T$65, "Mero", 'DADOS PEIXES'!$V$16:$V$65, ">=30", 'DADOS PEIXES'!$V$16:$V$65, "<40" ) -> 0 | G30: =SUM(C30:D30:E30:F30) -> 0 | H30: =AVERAGE(C30:D30:E30:F30) -> 0 | I30: =STDEV(C30:D30:E30:F30) -> 0
B31: Mero 40-50 cm | C31: =SUMIFS('DADOS PEIXES'!$I$16:$I$65, 'DADOS PEIXES'!$F$16:$F$65, "Mero", 'DADOS PEIXES'!$H$16:$H$65, ">=40", 'DADOS PEIXES'!$H$16:$H$65, "<50" ) -> 0 | D31: =SUMIFS('DADOS PEIXES'!$M$16:$M$65, 'DADOS PEIXES'!$J$16:$J$65, "Mero", 'DADOS PEIXES'!$L$16:$L$65, ">=40", 'DADOS PEIXES'!$L$16:$L$65, "<50" ) -> 0 | E31: =SUMIFS('DADOS PEIXES'!$S$16:$S$65, 'DADOS PEIXES'!$P$16:$P$65, "Mero", 'DADOS PEIXES'!$R$16:$R$65, ">=40", 'DADOS PEIXES'!$R$16:$R$65, "<50" ) -> 0 | F31: =SUMIFS('DADOS PEIXES'!$W$16:$W$65, 'DADOS PEIXES'!$T$16:$T$65, "Mero", 'DADOS PEIXES'!$V$16:$V$65, ">=40", 'DADOS PEIXES'!$V$16:$V$65, "<50" ) -> 0 | G31: =SUM(C31:D31:E31:F31) -> 0 | H31: =AVERAGE(C31:D31:E31:F31) -> 0 | I31: =STDEV(C31:D31:E31:F31) -> 0
B32: Mero 50-60 cm | C32: =SUMIFS('DADOS PEIXES'!$I$16:$I$65, 'DADOS PEIXES'!$F$16:$F$65, "Mero", 'DADOS PEIXES'!$H$16:$H$65, ">=50", 'DADOS PEIXES'!$H$16:$H$65, "<60" ) -> 0 | D32: =SUMIFS('DADOS PEIXES'!$M$16:$M$65, 'DADOS PEIXES'!$J$16:$J$65, "Mero", 'DADOS PEIXES'!$L$16:$L$65, ">=50", 'DADOS PEIXES'!$L$16:$L$65, "<60" ) -> 0 | E32: =SUMIFS('DADOS PEIXES'!$S$16:$S$65, 'DADOS PEIXES'!$P$16:$P$65, "Mero", 'DADOS PEIXES'!$R$16:$R$65, ">=50", 'DADOS PEIXES'!$R$16:$R$65, "<60" ) -> 0 | F32: =SUMIFS('DADOS PEIXES'!$W$16:$W$65, 'DADOS PEIXES'!$T$16:$T$65, "Mero", 'DADOS PEIXES'!$V$16:$V$65, ">=50", 'DADOS PEIXES'!$V$16:$V$65, "<60" ) -> 0 | G32: =SUM(C32:D32:E32:F32) -> 0 | H32: =AVERAGE(C32:D32:E32:F32) -> 0 | I32: =STDEV(C32:D32:E32:F32) -> 0
B33: Mero >60 cm | C33: =SUMIFS('DADOS PEIXES'!$I$16:$I$65, 'DADOS PEIXES'!$F$16:$F$65, "Mero", 'DADOS PEIXES'!$H$16:$H$65, ">=60") -> 0 | D33: =SUMIFS('DADOS PEIXES'!$M$16:$M$65, 'DADOS PEIXES'!$J$16:$J$65, "Mero", 'DADOS PEIXES'!$L$16:$L$65, ">=60") -> 0 | E33: =SUMIFS('DADOS PEIXES'!$S$16:$S$65, 'DADOS PEIXES'!$P$16:$P$65, "Mero", 'DADOS PEIXES'!$R$16:$R$65, ">60") -> 0 | F33: =SUMIFS('DADOS PEIXES'!$W$16:$W$65, 'DADOS PEIXES'!$T$16:$T$65, "Mero", 'DADOS PEIXES'!$V$16:$V$65, ">60") -> 0 | G33: =SUM(C33:D33:E33:F33) -> 0 | H33: =AVERAGE(C33:D33:E33:F33) -> 0 | I33: =STDEV(C33:D33:E33:F33) -> 0
B34: Total mero | C34: =SUM(C29:C33) -> 0 | D34: =SUM(D29:D33) -> 0 | E34: =SUM(E29:E33) -> 0 | F34: =SUM(F29:F33) -> 0 | G34: =SUM(G29:G33) -> 0 | H34: =AVERAGE(C34:D34:E34:F34) -> 0 | I34: =STDEV(C34:D34:E34:F34) -> 0
B36: Garoupas >30 cm | C36: A | D36: B | E36: C | F36: D | G36: Total | H36: Média | I36: DP
B37: Garoupas 30-40 cm | C37: =SUMIFS('DADOS PEIXES'!$I$16:$I$65, 'DADOS PEIXES'!$F$16:$F$65, "Garoupas > 30cm", 'DADOS PEIXES'!$H$16:$H$65, ">=30", 'DADOS PEIXES'!$H$16:$H$65, "<40" ) -> 0 | D37: =SUMIFS('DADOS PEIXES'!$M$16:$M$65, 'DADOS PEIXES'!$J$16:$J$65, "Garoupas > 30cm", 'DADOS PEIXES'!$L$16:$L$65, ">=30", 'DADOS PEIXES'!$L$16:$L$65, "<40" ) -> 0 | E37: =SUMIFS('DADOS PEIXES'!$S$16:$S$65, 'DADOS PEIXES'!$P$16:$P$65, "Garoupas > 30cm", 'DADOS PEIXES'!$R$16:$R$65, ">=30", 'DADOS PEIXES'!$R$16:$R$65, "<40" ) -> 0 | F37: =SUMIFS('DADOS PEIXES'!$W$16:$W$65, 'DADOS PEIXES'!$T$16:$T$65, "Garoupas > 30cm", 'DADOS PEIXES'!$V$16:$V$65, ">=30", 'DADOS PEIXES'!$V$16:$V$65, "<40" ) -> 0 | G37: =SUM(C37:D37:E37:F37) -> 0 | H37: =AVERAGE(C37:D37:E37:F37) -> 0 | I37: =STDEV(C37:D37:E37:F37) -> 0
B38: Garoupas 40-50 cm | C38: =SUMIFS('DADOS PEIXES'!$I$16:$I$65, 'DADOS PEIXES'!$F$16:$F$65, "Garoupas > 30cm", 'DADOS PEIXES'!$H$16:$H$65, ">=40", 'DADOS PEIXES'!$H$16:$H$65, "<50" ) -> 0 | D38: =SUMIFS('DADOS PEIXES'!$M$16:$M$65, 'DADOS PEIXES'!$J$16:$J$65, "Garoupas > 30cm", 'DADOS PEIXES'!$L$16:$L$65, ">=40", 'DADOS PEIXES'!$L$16:$L$65, "<50" ) -> 0 | E38: =SUMIFS('DADOS PEIXES'!$S$16:$S$65, 'DADOS PEIXES'!$P$16:$P$65, "Garoupas > 30cm", 'DADOS PEIXES'!$R$16:$R$65, ">=40", 'DADOS PEIXES'!$R$16:$R$65, "<50" ) -> 0 | F38: =SUMIFS('DADOS PEIXES'!$W$16:$W$65, 'DADOS PEIXES'!$T$16:$T$65, "Garoupas > 30cm", 'DADOS PEIXES'!$V$16:$V$65, ">=40", 'DADOS PEIXES'!$V$16:$V$65, "<50" ) -> 0 | G38: =SUM(C38:D38:E38:F38) -> 0 | H38: =AVERAGE(C38:D38:E38:F38) -> 0 | I38: =STDEV(C38:D38:E38:F38) -> 0
B39: Garoupas 50-60 cm | C39: =SUMIFS('DADOS PEIXES'!$I$16:$I$65, 'DADOS PEIXES'!$F$16:$F$65, "Garoupas > 30cm", 'DADOS PEIXES'!$H$16:$H$65, ">=50", 'DADOS PEIXES'!$H$16:$H$65, "<60" ) -> 0 | D39: =SUMIFS('DADOS PEIXES'!$M$16:$M$65, 'DADOS PEIXES'!$J$16:$J$65, "Garoupas > 30cm", 'DADOS PEIXES'!$L$16:$L$65, ">=50", 'DADOS PEIXES'!$L$16:$L$65, "<60" ) -> 0 | E39: =SUMIFS('DADOS PEIXES'!$S$16:$S$65, 'DADOS PEIXES'!$P$16:$P$65, "Garoupas > 30cm", 'DADOS PEIXES'!$R$16:$R$65, ">=50", 'DADOS PEIXES'!$R$16:$R$65, "<60" ) -> 0 | F39: =SUMIFS('DADOS PEIXES'!$W$16:$W$65, 'DADOS PEIXES'!$T$16:$T$65, "Garoupas > 30cm", 'DADOS PEIXES'!$V$16:$V$65, ">=50", 'DADOS PEIXES'!$V$16:$V$65, "<60" ) -> 0 | G39: =SUM(C39:D39:E39:F39) -> 0 | H39: =AVERAGE(C39:D39:E39:F39) -> 0 | I39: =STDEV(C39:D39:E39:F39) -> 0
B40: Garoupas >60 cm | C40: =SUMIFS('DADOS PEIXES'!$I$16:$I$65, 'DADOS PEIXES'!$F$16:$F$65, "Garoupas > 30cm", 'DADOS PEIXES'!$H$16:$H$65, ">=60") -> 0 | D40: =SUMIFS('DADOS PEIXES'!$M$16:$M$65, 'DADOS PEIXES'!$J$16:$J$65, "Garoupas > 30cm", 'DADOS PEIXES'!$L$16:$L$65, ">=60") -> 0 | E40: =SUMIFS('DADOS PEIXES'!$S$16:$S$65, 'DADOS PEIXES'!$P$16:$P$65, "Garoupas > 30cm", 'DADOS PEIXES'!$R$16:$R$65, ">60") -> 0 | F40: =SUMIFS('DADOS PEIXES'!$W$16:$W$65, 'DADOS PEIXES'!$T$16:$T$65, "Garoupas > 30cm", 'DADOS PEIXES'!$V$16:$V$65, ">60") -> 0 | G40: =SUM(C40:D40:E40:F40) -> 0 | H40: =AVERAGE(C40:D40:E40:F40) -> 0 | I40: =STDEV(C40:D40:E40:F40) -> 0
B41: Total garoupas >30 cm | C41: =SUM(C37:C40) -> 0 | D41: =SUM(D37:D40) -> 0 | E41: =SUM(E37:E40) -> 0 | F41: =SUM(F37:F40) -> 0 | G41: =SUM(G37:G40) -> 0 | H41: =AVERAGE(C41:D41:E41:F41) -> 0 | I41: =STDEV(C41:D41:E41:F41) -> 0
B44: Dados registrados por (nome completo): | C44: Edmilson do Carmo
B46: INVERTEBRADOS | C46: A | D46: B | E46: C | F46: D | G46: Total | H46: Média | I46: DP
B47: Anêmona | C47: =IF('DADOS INVERTEBRADOS'!G24 = "", "", 'DADOS INVERTEBRADOS'!G24) -> 0 | D47: =IF('DADOS INVERTEBRADOS'!J24 = "", "", 'DADOS INVERTEBRADOS'!J24) -> 1 | E47: =IF('DADOS INVERTEBRADOS'!M24 = "", "", 'DADOS INVERTEBRADOS'!M24) -> 0 | F47: =IF('DADOS INVERTEBRADOS'!P24 = "", "", 'DADOS INVERTEBRADOS'!P24) -> 1 | G47: =SUM(C47:D47:E47:F47) -> 2 | H47: =AVERAGE(C47:D47:E47:F47) -> 0.5 | I47: =STDEV(C47:D47:E47:F47) -> 0.57735027
B48: Búzio | C48: =IF('DADOS INVERTEBRADOS'!G25 = "", "", 'DADOS INVERTEBRADOS'!G25) -> 1 | D48: =IF('DADOS INVERTEBRADOS'!J25 = "", "", 'DADOS INVERTEBRADOS'!J25) -> 0 | E48: =IF('DADOS INVERTEBRADOS'!M25 = "", "", 'DADOS INVERTEBRADOS'!M25) -> 0 | F48: =IF('DADOS INVERTEBRADOS'!P25 = "", "", 'DADOS INVERTEBRADOS'!P25) -> 0 | G48: =SUM(C48:D48:E48:F48) -> 1 | H48: =AVERAGE(C48:D48:E48:F48) -> 0.25 | I48: =STDEV(C48:D48:E48:F48) -> 0.5
B49: Camarão-palhaço | C49: =IF('DADOS INVERTEBRADOS'!G26 ="","",'DADOS INVERTEBRADOS'!G26) -> 0 | D49: =IF('DADOS INVERTEBRADOS'!J26 ="","",'DADOS INVERTEBRADOS'!J26) -> 0 | E49: =IF('DADOS INVERTEBRADOS'!M26 ="","",'DADOS INVERTEBRADOS'!M26) -> 0 | F49: =IF('DADOS INVERTEBRADOS'!P26 ="","",'DADOS INVERTEBRADOS'!P26) -> 0 | G49: =SUM(C49:D49:E49:F49) -> 0 | H49: =AVERAGE(C49:D49:E49:F49) -> 0 | I49: =STDEV(C49:D49:E49:F49) -> 0
B50: Estrela-do-mar | C50: =IF('DADOS INVERTEBRADOS'!G28 = "", "", 'DADOS INVERTEBRADOS'!G28) -> 0 | D50: =IF('DADOS INVERTEBRADOS'!J28 = "", "", 'DADOS INVERTEBRADOS'!J28) -> 0 | E50: =IF('DADOS INVERTEBRADOS'!M28 = "", "", 'DADOS INVERTEBRADOS'!M28) -> 0 | F50: =IF('DADOS INVERTEBRADOS'!P28 = "", "", 'DADOS INVERTEBRADOS'!P28) -> 1 | G50: =SUM(C50:D50:E50:F50) -> 1 | H50: =AVERAGE(C50:D50:E50:F50) -> 0.25 | I50: =STDEV(C50:D50:E50:F50) -> 0.5
B51: Gorgônia | C51: =IF('DADOS INVERTEBRADOS'!G29 = "", "", 'DADOS INVERTEBRADOS'!G29) -> 80 | D51: =IF('DADOS INVERTEBRADOS'!J29 = "", "", 'DADOS INVERTEBRADOS'!J29) -> 46 | E51: =IF('DADOS INVERTEBRADOS'!M29 = "", "", 'DADOS INVERTEBRADOS'!M29) -> 112 | F51: =IF('DADOS INVERTEBRADOS'!P29 = "", "", 'DADOS INVERTEBRADOS'!P29) -> 75 | G51: =SUM(C51:D51:E51:F51) -> 313 | H51: =AVERAGE(C51:D51:E51:F51) -> 78.25 | I51: =STDEV(C51:D51:E51:F51) -> 27.035471
...

Sheet GRÁFICOS
B2: COMPLETE O TÍTULO DOS GRÁFICOS ONDE ESTÁ INDICADO A AZUL. PARA ALTERAR O TEXTO PARA PRETO, SELECIONE O TEXTO, CLIQUE NA OPÇÃO COR DE FONTE NA BARRA DE FERRAMENTAS FORMATAR E SELECIONE PRETO.
F4: Gráficos do Reef Check Brasil
B5: Dados do Reef Check Brasil
B8: Peixe | C8: Média | D8: EP
B9: Borboletas | C9: =SUMÁRIO!H12 -> 10 | D9: =SUM(SUMÁRIO!I12/SQRT(4)) -> 4.5643546
B10: Cirurgiões > 20 cm | C10: =SUMÁRIO!H13 -> 0 | D10: =SUM(SUMÁRIO!I13/SQRT(4)) -> 0
B11: Cirurgiões ≤ 20 cm | C11: =SUMÁRIO!H14 -> 17.5 | D11: =SUM(SUMÁRIO!I14/SQRT(4)) -> 12.479984
B12: Garoupas > 30 cm | C12: =SUMÁRIO!H15 -> 0 | D12: =SUM(SUMÁRIO!I15/SQRT(4)) -> 0
B13: Garoupas ≤ 30 cm | C13: =SUMÁRIO!H16 -> 0.25 | D13: =SUM(SUMÁRIO!I16/SQRT(4)) -> 0.25
B14: Mero | C14: =SUMÁRIO!H17 -> 0 | D14: =SUM(SUMÁRIO!I17/SQRT(4)) -> 0
B15: Móreias | C15: =SUMÁRIO!H18 -> 0 | D15: =SUM(SUMÁRIO!I18/SQRT(4)) -> 0
B16: Ornamentais | C16: =SUMÁRIO!H19 -> 6 | D16: =SUM(SUMÁRIO!I19/SQRT(4)) -> 2.2730303
B17: Papagaios > 20 cm | C17: =SUMÁRIO!H20 -> 0 | D17: =SUM(SUMÁRIO!I20/SQRT(4)) -> 0
B18: Papagaios ≤ 20 cm | C18: =SUMÁRIO!H21 -> 2 | D18: =SUM(SUMÁRIO!I21/SQRT(4)) -> 2
B19: Raias | C19: =SUMÁRIO!H22 -> 0 | D19: =SUM(SUMÁRIO!I22/SQRT(4)) -> 0
B20: Tubarões | C20: =SUMÁRIO!H23 -> 0.25 | D20: =SUM(SUMÁRIO!I23/SQRT(4)) -> 0.25
... B23: Xiras ≤ 10 cm | C23: =SUMÁRIO!H26 -> 27.5 | D23: =SUM(SUMÁRIO!I26/SQRT(4)) -> 13.124405
B26: Mero (cm) | C26: Média | D26: EP
B27: 20-30 | C27: =SUMÁRIO!H29 -> 0 | D27: =SUM(SUMÁRIO!I29/SQRT(4)) -> 0
B28: 30-40 | C28: =SUMÁRIO!H30 -> 0 | D28: =SUM(SUMÁRIO!I30/SQRT(4)) -> 0
B29: 40-50 | C29: =SUMÁRIO!H31 -> 0 | D29: =SUM(SUMÁRIO!I31/SQRT(4)) -> 0
B30: 50-60 | C30: =SUMÁRIO!H32 -> 0 | D30: =SUM(SUMÁRIO!I32/SQRT(4)) -> 0
B31: >60 | C31: =SUMÁRIO!H33 -> 0 | D31: =SUM(SUMÁRIO!I33/SQRT(4)) -> 0
B34: Garoupas (cm) | C34: Média | D34: EP
B35: 30-40 | C35: =SUMÁRIO!H37 -> 0 | D35: =SUM(SUMÁRIO!I37/SQRT(4)) -> 0
B36: 40-50 | C36: =SUMÁRIO!H38 -> 0 | D36: =SUM(SUMÁRIO!I38/SQRT(4)) -> 0
B37: 50-60 | C37: =SUMÁRIO!H39 -> 0 | D37: =SUM(SUMÁRIO!I39/SQRT(4)) -> 0
B38: >60 | C38: =SUMÁRIO!H40 -> 0 | D38: =SUM(SUMÁRIO!I40/SQRT(4)) -> 0
B41: Invertebrados | C41: Média | D41: EP
B42: Anêmona | C42: =SUMÁRIO!H47 -> 0.5 | D42: =SUM(SUMÁRIO!I47/SQRT(4)) -> 0.28867513
B43: Búzio | C43: =SUMÁRIO!H48 -> 0.25 | D43: =SUM(SUMÁRIO!I48/SQRT(4)) -> 0.25
B44: Camarão-palhaço | C44: =SUMÁRIO!H49 -> 0 | D44: =SUM(SUMÁRIO!I49/SQRT(4)) -> 0
B45: Estrela-do-mar | C45: =SUMÁRIO!H50 -> 0.25 | D45: =SUM(SUMÁRIO!I50/SQRT(4)) -> 0.25
B46: Gorgônia | C46: =SUMÁRIO!H51 -> 78.25 | D46: =SUM(SUMÁRIO!I51/SQRT(4)) -> 13.517735
B47: Lagosta | C47: =SUMÁRIO!H52 -> 0.25 | D47: =SUM(SUMÁRIO!I52/SQRT(4)) -> 0.25
B48: Ouriço branco | C48: =SUMÁRIO!H53 -> 0 | D48: =SUM(SUMÁRIO!I53/SQRT(4)) -> 0
B49: Ouriço comum (n/m2) | C49: =SUMÁRIO!H54 -> 12.5 | D49: =SUM(SUMÁRIO!I54/SQRT(4)) -> 1.8929694
B50: Ouriço diadema | C50: =SUMÁRIO!H55 -> 0 | D50: =SUM(SUMÁRIO!I55/SQRT(4)) -> 0
B51: Ouriço satélite | C51: =SUMÁRIO!H56 -> 0 | D51: =SUM(SUMÁRIO!I56/SQRT(4)) -> 0
B52: Poliqueta-de-fogo | C52: =SUMÁRIO!H57 -> 0 | D52: =SUM(SUMÁRIO!I57/SQRT(4)) -> 0
...

Sheet DADOS PEIXES
F2: PREENCHA OS ESPAÇOS EM BRANCO | AA2: sem registro
B3: Espécies: | C3: Móreias | Z3: Borboletas | AA3: novo registro
B4: não identificada | C4: Enchelycore carychroa | D4: Vermelhos (Lutjanidae) | F4: Em caso de ser registrada uma espécie não descrita aqui, | P4: Em caso de ser registrada uma espécie não descrita aqui, | Z4: Bobós, papagaios > 20 cm | AA4: não identificada
B5: novo registro | C5: Gymnothorax funebris | D5: Lutjanus alexandrei | F5: selecione como "novo registro" e adicione o nome em Observações. | P5: selecione como "novo registro" e adicione o nome em Observações. | Z5: Bobós, papagaios ≤ 20 cm | AA5: Abudefduf saxatilis
B6: sem registro | C6: Gymnothorax miliaris | D6: Lutjanus analis | J6: Classes peixes indicadores | T6: Classes peixes indicadores | Z6: Cirurgiões > 20 cm | AA6: Acanthostracion polygonius
C7: Gymnothorax moringa | D7: Lutjanus cyanopterus | F7: Em caso de identificar apenas da classe do indicador, | P7: Em caso de identificar apenas da classe do indicador, | Z7: Cirurgiões ≤ 20 cm | AA7: Acanthostracion quadricornis
B8: Borboletas (Chaetodontidae) | C8: Gymnothorax vicinus | D8: Lutjanus jocu | F8: preencha a coluna Espécie como "não identificada". | J8: Borboletas | K8: Garoupas > 30cm | L8: Raias | P8: preencha a coluna Espécie como "não identificada". | T8: Borboletas | U8: Garoupas > 30cm | V8: Raias | Z8: Garoupas > 30cm | AA8: Acanthurus bahianus
B9: Chaetodon ocellatus | C9: Gymnothorax sp | D9: Lutjanus synagris | J9: Bobós, papagaios > 20 cm | K9: Garoupas ≤ 30cm | L9: Tubarões | T9: Bobós, papagaios > 20 cm | U9: Garoupas ≤ 30cm | V9: Tubarões | Z9: Garoupas ≤ 30cm | AA9: Acanthurus chirurgus
B10: Chaetodon striatus | C10: Muraena pavonina | D10: Ocyurus chrysurus | F10: Todas as classes de indicadores devem estar presentes na lista | J10: Bobós, papagaios ≤ 20 cm | K10: Mero | L10: Vermelhos | P10: Todas as classes de indicadores devem estar presentes na lista | T10: Bobós, papagaios ≤ 20 cm | U10: Mero | V10: Vermelhos | Z10: Mero | AA10: Acanthurus coeruleus
C11: Muraena retifera | F11: de cada segmento. Em caso de não haver registro dessa classe, | J11: Cirurgiões > 20 cm | K11: Moréias | L11: Xiras > 10 cm | P11: de cada segmento. Em caso de não haver registro dessa classe, | T11: Cirurgiões > 20 cm | U11: Moréias | V11: Xiras > 10 cm | Z11: Moréias | AA11: Acanthurus sp
B12: Cirurgiões (Acanthuridae) | D12: Papagaios (Scarinae) | F12: preencha como "sem registro" na coluna Espécie. | J12: Cirurgiões ≤ 20 cm | K12: Ornamentais | L12: Xiras ≤ 10 cm | P12: preencha como "sem registro" na coluna Espécie. | T12: Cirurgiões ≤ 20 cm | U12: Ornamentais | V12: Xiras ≤ 10 cm | Z12: Não é indicador | AA12: Albula vulpes
B13: Acanthurus bahianus | C13: Ornamentais | D13: Cryptotomus roseus | Z13: Ornamentais | AA13: Alphestes afer
B14: Acanthurus chirurgus | C14: Bodianus pulchellus | D14: Scarus trispinosus | F14: SEGMENTO A | J14: SEGMENTO B | P14: SEGMENTO C | T14: SEGMENTO D | Z14: Raias | AA14: Aluterus scriptus
B15: Acanthurus coeruleus | C15: Bodianus rufus | D15: Scarus zelindae | F15: Indicadores | G15: Espécie | H15: Comprimento (cm) | I15: Número | J15: Indicadores | K15: Espécie | L15: Comprimento (cm) | M15: Número | P15: Indicadores | Q15: Espécie | R15: Comprimento (cm) | S15: Número | T15: Indicadores | U15: Espécie | V15: Comprimento (cm) | W15: Número | Z15: Tubarões | AA15: Amblycirrhitus pinos
B16: Acanthurus sp | C16: Elacatinus figaro | D16: Sparisoma amplum | F16: Borboletas | G16: Chaetodon striatus | H16: 2 | I16: 5 | J16: Borboletas | K16: chaetodon striatus | L16: 2 | M16: 20 | P16: Borboletas | Q16: Chaetodon striatus | R16: 2 | S16: 15 | T16: Vermelhos | U16: Ocyurus chrysurus | V16: 1 | W16: 2 | Z16: Vermelhos | AA16: Anisotremus moricandi
C17: Elacatinus phthirophagus | D17: Sparisoma axillare | F17: Xiras ≤ 10 cm | G17: Haemulon plumieri | H17: 4 | I17: 10 | J17: Xiras ≤ 10 cm | K17: Haemulon aurolineatum | L17: 1 | M17: 2 | P17: Xiras ≤ 10 cm | Q17: Haemulon plumieri | R17: 2 | S17: 60 | T17: Vermelhos | U17: Ocyurus chrysurus | V17: 4 | W17: 2 | Z17: Xiras > 10 cm | AA17: Anisotremus surinamensis
B18: Garoupas (Epinephelidae) | C18: Gramma brasiliensis | D18: Sparisoma frondosum | F18: Xiras ≤ 10 cm | G18: anisotremus virginicus | H18: 3 | I18: 4 | J18: Xiras ≤ 10 cm | K18: Haemulon aurolineatum | L18: 3 | M18: 10 | P18: Garoupas ≤ 30cm | Q18: Cephalopholis fulva | R18: 7 | S18: 1 | T18: Não é indicador | U18: Halichoeres brasiliensis | V18: 6 | W18: 1 | Z18: Xiras ≤ 10 cm | AA18: Anisotremus virginicus
B19: Alphestes afer | C19: Holacanthus ciliaris | D19: Sparisoma radians | F19: Não é indicador | G19: Halichoeres brasiliensis | H19: 3 | I19: 2 | J19: Xiras ≤ 10 cm | K19: Haemulon plumieri | L19: 4 | M19: 8 | P19: Cirurgiões ≤ 20 cm | Q19: Acanthurus chirurgus | R19: 3 | S19: 4 | T19: Não é indicador | U19: Stegastes fuscus | V19: 2 | W19: 5 | AA19: Apogon americanus
B20: Cephalopholis fulva | C20: Holacanthus tricolor | D20: Sparisoma sp | F20: Cirurgiões ≤ 20 cm | G20: Acanthurus coeruleus | H20: 3 | I20: 3 | J20: Xiras ≤ 10 cm | K20: anisotremus virginicus | L20: 4 | M20: 6 | P20: Cirurgiões ≤ 20 cm | Q20: Acanthurus coeruleus | R20: 4 | S20: 50 | T20: Não é indicador | U20: Holocentrus adscensionis | V20: 3 | W20: 4 | AA20: Archosargus rhomboidalis
B21: Cephalopholis furcifer | C21: Microspathodon chrysurus | F21: Não é indicador | G21: stegastes fuscus | H21: 3 | I21: 13 | J21: Xiras ≤ 10 cm | K21: Haemulon plumieri | L21: 4 | M21: 10 | P21: Não é indicador | Q21: stegastes fuscus | R21: 3 | S21: 4 | T21: Ornamentais | U21: Pomacanthus paru | V21: 6 | W21: 3 | AA21: Aulostomus maculatus
B22: Dermatolepis inermis | C22: Pomacanthus arcuatus | D22: Xiras (Haemulidae) | F22: Não é indicador | G22: abudefduf saxatilis | H22: 2 | I22: 6 | J22: vermelhos | K22: lutjanus jocu | L22: 5 | M22: 2 | P22: Ornamentais | Q22: Elacatinus figaro | R22: 2 | S22: 5 | T22: Ornamentais | U22: Elacatinus figaro | V22: 1 | W22: 4 | AA22: Balistes vetula
B23: Epinephelus adscencionis | C23: Pomacanthus paru | D23: Anisotremus moricandi | J23: Bobós, papagaios ≤ 20 cm | K23: Sparisoma frondosum | L23: 4 | M23: 5 | P23: Ornamentais | Q23: Elacatinus figaro | R23: 1 | S23: 1 | AA23: Bodianus pulchellus
B24: Epinephelus morio | D24: Anisotremus surinamensis | J24: Bobós, papagaios ≤ 20 cm | K24: Scarus trispinosus | L24: 4 | M24: 3 | P24: Não é indicador | Q24: Rypticus saponaceus | R24: 4 | S24: 1 | AA24: Bodianus rufus
B25: Menophorus dubius | C25: Raias | D25: Anisotremus virginicus | J25: Cirurgiões ≤ 20 cm | K25: Acanthurus coeruleus | L25: 6 | M25: 13 | AA25: Bothus lunatus
B26: Mycteroperca bonaci | C26: Dasyatis americana | D26: Haemulon aurolineatum | J26: Tubarões | K26: Ginglymostoma cirratum | L26: 80 | M26: 1 | AA26: Calamus penna
B27: Mycteroperca interstitialis | C27: Dasyatis marianae | D27: Haemulon chrysargyreum | J27: Ornamentais | K27: Pomacanthus paru | L27: 5 | M27: 5 | AA27: Cantherhines macrocerus
D28: Haemulon parra | J28: Ornamentais | K28: Pomacanthus paru | L28: 3 | M28: 5 | AA28: Cantherhines pullus
B29: Mero | C29: Tubarões | D29: Haemulon plumieri | J29: Ornamentais | K29: Pomacanthus arcuatus | L29: 5 | M29: 1 | AA29: Canthidermis sufflamen
B30: Epinephelus itajara | C30: Carcharhinus perezi | D30: Haemulon squamipinna | J30: Não é indicador | K30: Stegastes fuscus | L30: 3 | M30: 10 | AA30: Canthigaster figueiredoi
C31: Ginglymostoma cirratum | D31: Haemulon sp | J31: Não é indicador | K31: Pseudupeneus maculatus | L31: 4 | M31: 15 | AA31: Carangoides bartholomaei
C32: Negaprion brevirostris | J32: Não é indicador | K32: abudefduf saxatilis | L32: 2 | M32: 15 | AA32: Caranx crysos
AA33: Caranx hippos
B34: Não indicadores | AA34: Caranx latus
AA35: Caranx lugubris
B36: Abudefduf saxatilis | C36: Echeneis naucrates | D36: Ogcocephalus vespertilio | AA36: Caranx ruber
B37: Acanthostracion polygonius | C37: Emblemariopsis signifera | D37: Oligoplites sp | AA37: Caranx sp
B38: Acanthostracion quadricornis | C38: Enneanectes altivelis | D38: Ophioblennius trinitatis | AA38: Carcharhinus perezi
B39: Albula vulpes | C39: Eucinostomus sp | D39: Parablennius sp | AA39: Cephalopholis fulva
B40: Aluterus scriptus | C40: Gnatholepis thompsoni | D40: Pareques acuminatus | AA40: Cephalopholis furcifer
B41: Amblycirrhitus pinos | C41: Gobiosoma sp | D41: Pempheris schomburgki | AA41: Chaetodipterus faber
...

Sheet DADOS INVERTEBRADOS
C2: Ouriço comum | E2: PREENCHA OS ESPAÇOS EM BRANCO | T2: sem registro
B3: Espécies: | C3: Echinometra lucunter | S3: Anêmona | T3: novo registro
B4: sem registro | E4: Em caso de ser registrada uma espécie não descrita aqui, selecione como "novo registro" e adicione o nome em Observações. | J4: Invertebrados indicadores | S4: Buzio | T4: não identificada
B5: novo registro | C5: Ouriço diadema | S5: Camarão-palhaço | T5: Aplysia dactylomela
B6: não identificada | C6: Diadema antillarum | L6: Caranguejo | N6: Ouriço branco | O6: Pepino-do-mar | S6: Caranguejo | T6: Bellactis ilkalyseae
E7: Em caso de identificar apenas da classe do indicador, preencha a coluna Espécie como | K7: Anêmona | L7: Estrela-do-mar | N7: Ouriço comum | O7: Poliqueta-de-fogo | S7: Estrela-do-mar | T7: Carpilius corallinus
B8: Anêmona | C8: Ouriço satélite | E8: "não identificada". | K8: Búzio | L8: Gorgônia | N8: Ouriço diadema | O8: Polvo | S8: Gorgônia | T8: Cassis flammea
B9: Condylactis gigantea | C9: Eucidaris tribuloides | K9: Camarão-palhaço | L9: Lagosta | N9: Ouriço satélite | O9: Outros | S9: Lagosta | T9: Cassis tuberosa
S10: Ouriço Branco | T10: Cassis sp
E11: SEGMENTO A | H11: SEGMENTO B | K11: SEGMENTO C | N11: SEGMENTO D | S11: Ouriço Comum | T11: Condylactis gigantea
B12: Búzio | C12: Pepino-do-mar | E12: Indicadores | F12: Espécie | G12: Número/% | H12: Indicadores | I12: Espécie | J12: Número/% | K12: Indicadores | L12: Espécie | M12: Número/% | N12: Indicadores | O12: Espécie | P12: Número/% | S12: Ouriço Diadema | T12: Cypraea cinerea
B13: Cassis flammea | C13: Holotúria | E13: Coral (% de cobertura) | F13: estimativa | H13: Coral (% de cobertura) | I13: estimativa | K13: Coral (% de cobertura) | L13: estimativa | N13: Coral (% de cobertura) | O13: estimativa | S13: Ouriço Satélite | T13: Diadema antillarum
B14: Cassis tuberosa | E14: Coral branq (% da pop) | F14: estimativa | H14: Coral branq (% da pop) | I14: estimativa | K14: Coral branq (% da pop) | L14: estimativa | N14: Coral branq (% da pop) | O14: estimativa | S14: Outros | T14: Echinaster brasiliensis
B15: Cassis sp | C15: Poliqueta-de-fogo | E15: Coral branq (% da colônia) | F15: estimativa | H15: Coral branq (% da colônia) | I15: estimativa | K15: Coral branq (% da colônia) | L15: estimativa | N15: Coral branq (% da colônia) | O15: estimativa | S15: Pepino-do-mar | T15: Echinometra lucunter
B16: Voluta sp | C16: Hermodice carunculata | E16: Coral doente (% da pop) | F16: estimativa | H16: Coral doente (% da pop) | I16: estimativa | K16: Coral doente (% da pop) | L16: estimativa | N16: Coral doente (% da pop) | O16: estimativa | S16: Poliqueta de fogo | T16: Elacatinus figaro
E17: Coral quebrado (âncora/remo) | F17: contagem | H17: Coral quebrado (âncora/remo) | I17: contagem | K17: Coral quebrado (âncora/remo) | L17: contagem | N17: Coral quebrado (âncora/remo) | O17: contagem | S17: Polvo | T17: Elacatinus phthirophagus
B18: Camarão-palhaço | C18: Polvo | E18: Coral quebrado (mergulhador) | F18: contagem | H18: Coral quebrado (mergulhador) | I18: contagem | K18: Coral quebrado (mergulhador) | L18: contagem | N18: Coral quebrado (mergulhador) | O18: contagem | T18: Eucidaris tribuloides
B19: Stenopus hispidus | C19: Octopus insularis | E19: Coral quebrado (outro) | F19: contagem | H19: Coral quebrado (outro) | I19: contagem | K19: Coral quebrado (outro) | L19: contagem | N19: Coral quebrado (outro) | O19: contagem | T19: Gramma brasiliensis
B20: Periclimenes pedersoni | C20: Octopus vulgaris | E20: Lixo (pesca) | F20: contagem | G20: 1 | H20: Lixo (pesca) | I20: contagem | K20: Lixo (pesca) | L20: contagem | N20: Lixo (pesca) | O20: contagem | T20: Hermodice carunculata
B21: Periclimenes yucatanicus | E21: Lixo (plástico) | F21: contagem | H21: Lixo (plástico) | I21: contagem | K21: Lixo (plástico) | L21: contagem | N21: Lixo (plástico) | O21: contagem | T21: Holotúria
B22: Thor amboinensis | C22: Outros | E22: Lixo (outros) | F22: contagem | H22: Lixo (outros) | I22: contagem | K22: Lixo (outros) | L22: contagem | N22: Lixo (outros) | O22: contagem | T22: Lebrunia sp
C23: (não indicadores) | T23: Linckia sp
B24: Caranguejo | C24: Anêmonas pequenas | E24: Anêmona | F24: sem registro | G24: 0 | H24: Anêmona | I24: não identificada | J24: 1 | K24: Anêmona | L24: sem registro | M24: 0 | N24: Anêmona | O24: sem registro | P24: 1 | T24: Lirio-do-mar
B25: Carpilius corallinus | C25: Bellactis ilkalyseae | E25: Búzio | F25: não identificada | G25: 1 | H25: Búzio | I25: sem registro | J25: 0 | K25: Búzio | L25: sem registro | M25: 0 | N25: Búzio | O25: sem registro | P25: 0 | T25: Lithopoma sp
B26: Stenorhynchus seticornis | C26: Lebrunia sp | E26: Camarão-palhaço | F26: sem registro | G26: 0 | H26: Camarão-palhaço | I26: sem registro | J26: 0 | K26: Camarão-palhaço | L26: sem registro | M26: 0 | N26: Camarão-palhaço | O26: sem registro | P26: 0 | T26: Lytechinus variegatus
E27: Caranguejo | F27: sem registro | G27: 0 | H27: Caranguejo | I27: sem registro | J27: 0 | K27: Caranguejo | L27: sem registro | M27: 0 | N27: Caranguejo | O27: sem registro | P27: 0 | T27: Micromelo undata
B28: Estrela-do-mar | C28: Aplisia/lesma do mar | E28: Estrela-do-mar | F28: sem registro | G28: 0 | H28: Estrela-do-mar | I28: sem registro | J28: 0 | K28: Estrela-do-mar | L28: sem registro | M28: 0 | N28: Estrela-do-mar | O28: sem registro | P28: 1 | T28: Muriceopsis sulphurea
B29: Echinaster brasiliensis | C29: Aplysia dactylomela | E29: Gorgônia | F29: Muriceopsis sulphurea | G29: 80 | H29: Gorgônia | I29: Muriceopsis sulphurea | J29: 46 | K29: Gorgônia | L29: Muriceopsis sulphurea | M29: 112 | N29: Gorgônia | O29: Muriceopsis sulphurea | P29: 75 | T29: Muriceopsis sp
B30: Linckia sp | C30: Micromelo undata | E30: Lagosta | F30: sem registro | G30: 1 | H30: Lagosta | I30: sem registro | J30: 0 | K30: Lagosta | L30: sem registro | M30: 0 | N30: Lagosta | O30: sem registro | P30: 0 | T30: Octopus insularis
E31: Ouriço branco | F31: sem registro | G31: 0 | H31: Ouriço branco | I31: sem registro | J31: 0 | K31: Ouriço branco | L31: sem registro | M31: 0 | N31: Ouriço branco | O31: sem registro | P31: 0 | T31: Octopus vulgaris
B32: Gorgônia | C32: Búzios pequenos | E32: Ouriço comum | F32: echinometra lucunter | G32: 15 | H32: Ouriço comum | I32: echinometra lucunter | J32: 7 | K32: Ouriço comum | L32: echinometra lucunter | M32: 15 | N32: Ouriço comum | O32: echinometra lucunter | P32: 13 | T32: Ophioderma sp
B33: Muriceopsis sulphurea | C33: Cypraea cinerea | E33: Ouriço diadema | F33: sem registro | G33: 0 | H33: Ouriço diadema | I33: sem registro | J33: 0 | K33: Ouriço diadema | L33: sem registro | M33: 0 | N33: Ouriço diadema | O33: Diadema antilatum | P33: 0 | T33: Panulirus argus
B34: Muriceopsis sp | C34: Lithopoma sp | E34: Ouriço satélite | F34: sem registro | G34: 0 | H34: Ouriço satélite | I34: sem registro | J34: 0 | K34: Ouriço satélite | L34: sem registro | M34: 0 | N34: Ouriço satélite | O34: Eucidaris tribuloides | P34: 0 | T34: Panulirus echinatus
B35: Phyllogorgia dilatata | E35: Pepino-do-mar | F35: sem registro | G35: 0 | H35: Pepino-do-mar | I35: sem registro | J35: 0 | K35: Pepino-do-mar | L35: sem registro | M35: 0 | N35: Pepino-do-mar | O35: sem registro | P35: 0 | T35: Panulirus laevicauda
B36: Plexaurella dichotoma | C36: Cavaquinha | E36: Poliqueta-de-fogo | F36: sem registro | G36: 0 | H36: Poliqueta-de-fogo | I36: sem registro | J36: 0 | K36: Poliqueta-de-fogo | L36: sem registro | M36: 0 | N36: Poliqueta-de-fogo | O36: sem registro | P36: 0 | T36: Panulirus sp
B37: Plexaurella grandiflora | C37: Parribacus antarcticus | E37: Polvo | F37: sem registro | G37: 0 | H37: Polvo | I37: sem registro | J37: 0 | K37: Polvo | L37: não identificado | M37: 1 | N37: Polvo | O37: sem registro | P37: 0 | T37: Parribacus antarcticus
B38: Plexaurella regia | T38: Periclimenes pedersoni
B39: Plexaurella sp | C39: Crinóide | T39: Periclimenes yucatanicus
C40: Lirio-do-mar | T40: Phyllogorgia dilatata
B41: Lagosta | T41: Plexaurella dichotoma
...
