Workbook
Name classe_ind_real: '[1]DADOS ESPÉCIES'!$AF$3:$AF$15
Name classe_ind_real2: 'DADOS ESPÉCIES'!$AE$3:$AE$16
Name especies_substrato: 'DADOS ESPÉCIES'!$AD$2:$AD$75
Name saúde: 'DADOS ESPÉCIES'!$G$9,'DADOS ESPÉCIES'!$G$11,'DADOS ESPÉCIES'!$G$14,'DADOS ESPÉCIES'!$G$15

Sheet INSTRUÇÕES
A2: Para que os dados coletados por uma equipe sejam incorporados ao banco de dados do Reef Check Brasil, e sejam utilizados em relatórios e publicações sobre o estado dos ambientes recifais na costa brasileira, foram adaptadas planilhas excel para os diferentes tipos de indicadores amostrados pelo Reef Check Brasil
A3: COMO USAR AS PLANILHAS EXCEL
A5: 1. Insira os dados de substrato, registrados durante os censos, nas células em branco da folha DADOS ESPÉCIES. Para cada transecto (A, B, C e D) deverão ser preenchidas as colunas Classe Indicador, Espécie e Saúde. Nestes campos deverão ser inseridas as classes de substrato, as espécies identificadas de coral e outros organismos registrados, e ainda a saúde dos corais duros. No caso de substrato não vivo (areia, argila, cascalho e rocha) preencher o campo Espécie com "sem espécie".
A7: 2. Os dados deverão ser inseridos nas caixas em branco e, para facilitar a sua entrada, foram criadas listas de categorias, espécies e saúde dos corais, nas quais é apenas necessário selecionar a opção desejada. Novas ocorrências deverão ser preenchidas como “novo registro” e mencionadas no campo Observações ao final da folha.
A9: 3. Para cada transecto, verifique (na LINHA 64 da folha SUMÁRIO) se o total da coluna é igual a 40. Se a soma for menor que 40, confira na folha DADOS ESPÉCIES se há alguma célula em branco e confirme se todos os dados foram entrados corretamente.
A12: COMO ANALISAR OS DADOS
A14: 1. Ao inserir os dados, os gráficos são produzidos em simultâneo e automaticamente na folha GRÁFICOS.
A16: 2. Somente deverá ser preenchido o nome do sítio monitorado, a data e a profundidade dos transectos substituindo as palavras em azul no título do gráfico. Depois o texto deverá ser alterado para preto selecionando o botão de cor de texto na barra de ferramentas da fonte.
A18: 3. A página estará pronta para imprimir, e os gráficos desejados poderão ser selecionados e copiados em um documento Word.
A20: COMO ENVIAR OS DADOS
A22: 1. Primeiro nomeie a planilha utilizando o formato padrão:
A23: Nome do sítio, data (dd-mm-aa) e tipo de censo (sítio, peixes e invertebrados = faixa, substrato = PIT, e corais). A planilha de substrato deverá apenas conter o nome do sítio, a data (dd-mm-aa) e terminar com a palavra PIT.
... A47: Para estatística geral "Experimental Design and Data Analysis for Biologists", por G. P. Quinn e M. J. Keough, 2002, Cambridge University Press.

Sheet SUMÁRIO
D3: Sítio: | G3: Taquaruçu | L3: Região: | O3: Recife de Fora
D4: Profundidade: | G4: 2 | L4: Data: | O4: 43516
D5: Líder da equipe: | G5: Fábio Negrão | L5: Dados registrados por (nome completo): | O5: Flávia Guebert
D6: Horário (inicial e final): | G6: 09:00-10:15
D9: ACA | E9: alga calcária articulada | I9: NIA | J9: alga indicadora de nutriente | Q9: AR | R9: areia
D10: ACI | E10: alga calcária incrustante | I10: CM | J10: coral mole | N10: SP | O10: esponja | Q10: AG | R10: argila
D11: AF | E11: alga folhosa | I11: CD | J11: coral duro | N11: OT | O11: outros | Q11: CC | R11: cascalho
D12: TURF | E12: algas turf | I12: CRM | J12: coral recém morto | Q12: RC | R12: rocha
D14: SEGMENTO A | H14: SEGMENTO B | L14: SEGMENTO C | P14: SEGMENTO D
D15: 0 | E15: =IF('DADOS ESPÉCIES'!D20="", "", 'DADOS ESPÉCIES'!D20) -> CM | F15: 10 | G15: =IF('DADOS ESPÉCIES'!D40="", "", 'DADOS ESPÉCIES'!D40) -> RC | H15: 0 | I15: =IF('DADOS ESPÉCIES'!I20="", "", 'DADOS ESPÉCIES'!I20) -> CM | J15: 10 | K15: =IF('DADOS ESPÉCIES'!I40="", "", 'DADOS ESPÉCIES'!I40) -> CD | L15: 0 | M15: =IF('DADOS ESPÉCIES'!N20="", "", 'DADOS ESPÉCIES'!N20) -> CM | N15: 10 | O15: =IF('DADOS ESPÉCIES'!N40="", "", 'DADOS ESPÉCIES'!N40) -> CD | P15: 0 | Q15: =IF('DADOS ESPÉCIES'!S20="", "", 'DADOS ESPÉCIES'!S20) -> CD | R15: 10 | S15: =IF('DADOS ESPÉCIES'!S40="", "", 'DADOS ESPÉCIES'!S40) -> AF
D16: 0.5 | E16: =IF('DADOS ESPÉCIES'!D21="", "", 'DADOS ESPÉCIES'!D21) -> RC | F16: 10.5 | G16: =IF('DADOS ESPÉCIES'!D41="", "", 'DADOS ESPÉCIES'!D41) -> CD | H16: 0.5 | I16: =IF('DADOS ESPÉCIES'!I21="", "", 'DADOS ESPÉCIES'!I21) -> CM | J16: 10.5 | K16: =IF('DADOS ESPÉCIES'!I41="", "", 'DADOS ESPÉCIES'!I41) -> CD | L16: 0.5 | M16: =IF('DADOS ESPÉCIES'!N21="", "", 'DADOS ESPÉCIES'!N21) -> CM | N16: 10.5 | O16: =IF('DADOS ESPÉCIES'!N41="", "", 'DADOS ESPÉCIES'!N41) -> CD | P16: 0.5 | Q16: =IF('DADOS ESPÉCIES'!S21="", "", 'DADOS ESPÉCIES'!S21) -> RC | R16: 10.5 | S16: =IF('DADOS ESPÉCIES'!S41="", "", 'DADOS ESPÉCIES'!S41) -> CM
D17: 1 | E17: =IF('DADOS ESPÉCIES'!D22="", "", 'DADOS ESPÉCIES'!D22) -> CM | F17: 11 | G17: =IF('DADOS ESPÉCIES'!D42="", "", 'DADOS ESPÉCIES'!D42) -> RC | H17: 1 | I17: =IF('DADOS ESPÉCIES'!I22="", "", 'DADOS ESPÉCIES'!I22) -> CM | J17: 11 | K17: =IF('DADOS ESPÉCIES'!I42="", "", 'DADOS ESPÉCIES'!I42) -> RC | L17: 1 | M17: =IF('DADOS ESPÉCIES'!N22="", "", 'DADOS ESPÉCIES'!N22) -> CD | N17: 11 | O17: =IF('DADOS ESPÉCIES'!N42="", "", 'DADOS ESPÉCIES'!N42) -> CM | P17: 1 | Q17: =IF('DADOS ESPÉCIES'!S22="", "", 'DADOS ESPÉCIES'!S22) -> CD | R17: 11 | S17: =IF('DADOS ESPÉCIES'!S42="", "", 'DADOS ESPÉCIES'!S42) -> RC
D18: 1.5 | E18: =IF('DADOS ESPÉCIES'!D23="", "", 'DADOS ESPÉCIES'!D23) -> RC | F18: 11.5 | G18: =IF('DADOS ESPÉCIES'!D43="", "", 'DADOS ESPÉCIES'!D43) -> CM | H18: 1.5 | I18: =IF('DADOS ESPÉCIES'!I23="", "", 'DADOS ESPÉCIES'!I23) -> CRM | J18: 11.5 | K18: =IF('DADOS ESPÉCIES'!I43="", "", 'DADOS ESPÉCIES'!I43) -> RC | L18: 1.5 | M18: =IF('DADOS ESPÉCIES'!N23="", "", 'DADOS ESPÉCIES'!N23) -> RC | N18: 11.5 | O18: =IF('DADOS ESPÉCIES'!N43="", "", 'DADOS ESPÉCIES'!N43) -> CD | P18: 1.5 | Q18: =IF('DADOS ESPÉCIES'!S23="", "", 'DADOS ESPÉCIES'!S23) -> RC | R18: 11.5 | S18: =IF('DADOS ESPÉCIES'!S43="", "", 'DADOS ESPÉCIES'!S43) -> RC
D19: 2 | E19: =IF('DADOS ESPÉCIES'!D24="", "", 'DADOS ESPÉCIES'!D24) -> ACI | F19: 12 | G19: =IF('DADOS ESPÉCIES'!D44="", "", 'DADOS ESPÉCIES'!D44) -> RC | H19: 2 | I19: =IF('DADOS ESPÉCIES'!I24="", "", 'DADOS ESPÉCIES'!I24) -> CD | J19: 12 | K19: =IF('DADOS ESPÉCIES'!I44="", "", 'DADOS ESPÉCIES'!I44) -> CD | L19: 2 | M19: =IF('DADOS ESPÉCIES'!N24="", "", 'DADOS ESPÉCIES'!N24) -> RC | N19: 12 | O19: =IF('DADOS ESPÉCIES'!N44="", "", 'DADOS ESPÉCIES'!N44) -> CM | P19: 2 | Q19: =IF('DADOS ESPÉCIES'!S24="", "", 'DADOS ESPÉCIES'!S24) -> RC | R19: 12 | S19: =IF('DADOS ESPÉCIES'!S44="", "", 'DADOS ESPÉCIES'!S44) -> CM
D20: 2.5 | E20: =IF('DADOS ESPÉCIES'!D25="", "", 'DADOS ESPÉCIES'!D25) -> CM | F20: 12.5 | G20: =IF('DADOS ESPÉCIES'!D45="", "", 'DADOS ESPÉCIES'!D45) -> RC | H20: 2.5 | I20: =IF('DADOS ESPÉCIES'!I25="", "", 'DADOS ESPÉCIES'!I25) -> CM | J20: 12.5 | K20: =IF('DADOS ESPÉCIES'!I45="", "", 'DADOS ESPÉCIES'!I45) -> RC | L20: 2.5 | M20: =IF('DADOS ESPÉCIES'!N25="", "", 'DADOS ESPÉCIES'!N25) -> CD | N20: 12.5 | O20: =IF('DADOS ESPÉCIES'!N45="", "", 'DADOS ESPÉCIES'!N45) -> CD | P20: 2.5 | Q20: =IF('DADOS ESPÉCIES'!S25="", "", 'DADOS ESPÉCIES'!S25) -> CD | R20: 12.5 | S20: =IF('DADOS ESPÉCIES'!S45="", "", 'DADOS ESPÉCIES'!S45) -> RC
D21: 3 | E21: =IF('DADOS ESPÉCIES'!D26="", "", 'DADOS ESPÉCIES'!D26) -> CD | F21: 13 | G21: =IF('DADOS ESPÉCIES'!D46="", "", 'DADOS ESPÉCIES'!D46) -> ACI | H21: 3 | I21: =IF('DADOS ESPÉCIES'!I26="", "", 'DADOS ESPÉCIES'!I26) -> CM | J21: 13 | K21: =IF('DADOS ESPÉCIES'!I46="", "", 'DADOS ESPÉCIES'!I46) -> RC | L21: 3 | M21: =IF('DADOS ESPÉCIES'!N26="", "", 'DADOS ESPÉCIES'!N26) -> RC | N21: 13 | O21: =IF('DADOS ESPÉCIES'!N46="", "", 'DADOS ESPÉCIES'!N46) -> CD | P21: 3 | Q21: =IF('DADOS ESPÉCIES'!S26="", "", 'DADOS ESPÉCIES'!S26) -> CM | R21: 13 | S21: =IF('DADOS ESPÉCIES'!S46="", "", 'DADOS ESPÉCIES'!S46) -> CD
D22: 3.5 | E22: =IF('DADOS ESPÉCIES'!D27="", "", 'DADOS ESPÉCIES'!D27) -> ACI | F22: 13.5 | G22: =IF('DADOS ESPÉCIES'!D47="", "", 'DADOS ESPÉCIES'!D47) -> CD | H22: 3.5 | I22: =IF('DADOS ESPÉCIES'!I27="", "", 'DADOS ESPÉCIES'!I27) -> CD | J22: 13.5 | K22: =IF('DADOS ESPÉCIES'!I47="", "", 'DADOS ESPÉCIES'!I47) -> CM | L22: 3.5 | M22: =IF('DADOS ESPÉCIES'!N27="", "", 'DADOS ESPÉCIES'!N27) -> CM | N22: 13.5 | O22: =IF('DADOS ESPÉCIES'!N47="", "", 'DADOS ESPÉCIES'!N47) -> CD | P22: 3.5 | Q22: =IF('DADOS ESPÉCIES'!S27="", "", 'DADOS ESPÉCIES'!S27) -> AF | R22: 13.5 | S22: =IF('DADOS ESPÉCIES'!S47="", "", 'DADOS ESPÉCIES'!S47) -> CD
D23: 4 | E23: =IF('DADOS ESPÉCIES'!D28="", "", 'DADOS ESPÉCIES'!D28) -> RC | F23: 14 | G23: =IF('DADOS ESPÉCIES'!D48="", "", 'DADOS ESPÉCIES'!D48) -> RC | H23: 4 | I23: =IF('DADOS ESPÉCIES'!I28="", "", 'DADOS ESPÉCIES'!I28) -> RC | J23: 14 | K23: =IF('DADOS ESPÉCIES'!I48="", "", 'DADOS ESPÉCIES'!I48) -> CM | L23: 4 | M23: =IF('DADOS ESPÉCIES'!N28="", "", 'DADOS ESPÉCIES'!N28) -> CM | N23: 14 | O23: =IF('DADOS ESPÉCIES'!N48="", "", 'DADOS ESPÉCIES'!N48) -> CD | P23: 4 | Q23: =IF('DADOS ESPÉCIES'!S28="", "", 'DADOS ESPÉCIES'!S28) -> RC | R23: 14 | S23: =IF('DADOS ESPÉCIES'!S48="", "", 'DADOS ESPÉCIES'!S48) -> CM
D24: 4.5 | E24: =IF('DADOS ESPÉCIES'!D29="", "", 'DADOS ESPÉCIES'!D29) -> ACI | F24: 14.5 | G24: =IF('DADOS ESPÉCIES'!D49="", "", 'DADOS ESPÉCIES'!D49) -> ACI | H24: 4.5 | I24: =IF('DADOS ESPÉCIES'!I29="", "", 'DADOS ESPÉCIES'!I29) -> CD | J24: 14.5 | K24: =IF('DADOS ESPÉCIES'!I49="", "", 'DADOS ESPÉCIES'!I49) -> CM | L24: 4.5 | M24: =IF('DADOS ESPÉCIES'!N29="", "", 'DADOS ESPÉCIES'!N29) -> CD | N24: 14.5 | O24: =IF('DADOS ESPÉCIES'!N49="", "", 'DADOS ESPÉCIES'!N49) -> AF | P24: 4.5 | Q24: =IF('DADOS ESPÉCIES'!S29="", "", 'DADOS ESPÉCIES'!S29) -> RC | R24: 14.5 | S24: =IF('DADOS ESPÉCIES'!S49="", "", 'DADOS ESPÉCIES'!S49) -> CM
D25: 5 | E25: =IF('DADOS ESPÉCIES'!D30="", "", 'DADOS ESPÉCIES'!D30) -> RC | F25: 15 | G25: =IF('DADOS ESPÉCIES'!D50="", "", 'DADOS ESPÉCIES'!D50) -> CM | H25: 5 | I25: =IF('DADOS ESPÉCIES'!I30="", "", 'DADOS ESPÉCIES'!I30) -> RC | J25: 15 | K25: =IF('DADOS ESPÉCIES'!I50="", "", 'DADOS ESPÉCIES'!I50) -> RC | L25: 5 | M25: =IF('DADOS ESPÉCIES'!N30="", "", 'DADOS ESPÉCIES'!N30) -> CD | N25: 15 | O25: =IF('DADOS ESPÉCIES'!N50="", "", 'DADOS ESPÉCIES'!N50) -> AF | P25: 5 | Q25: =IF('DADOS ESPÉCIES'!S30="", "", 'DADOS ESPÉCIES'!S30) -> CD | R25: 15 | S25: =IF('DADOS ESPÉCIES'!S50="", "", 'DADOS ESPÉCIES'!S50) -> CM
D26: 5.5 | E26: =IF('DADOS ESPÉCIES'!D31="", "", 'DADOS ESPÉCIES'!D31) -> RC | F26: 15.5 | G26: =IF('DADOS ESPÉCIES'!D51="", "", 'DADOS ESPÉCIES'!D51) -> RC | H26: 5.5 | I26: =IF('DADOS ESPÉCIES'!I31="", "", 'DADOS ESPÉCIES'!I31) -> AF | J26: 15.5 | K26: =IF('DADOS ESPÉCIES'!I51="", "", 'DADOS ESPÉCIES'!I51) -> CD | L26: 5.5 | M26: =IF('DADOS ESPÉCIES'!N31="", "", 'DADOS ESPÉCIES'!N31) -> CM | N26: 15.5 | O26: =IF('DADOS ESPÉCIES'!N51="", "", 'DADOS ESPÉCIES'!N51) -> CM | P26: 5.5 | Q26: =IF('DADOS ESPÉCIES'!S31="", "", 'DADOS ESPÉCIES'!S31) -> CD | R26: 15.5 | S26: =IF('DADOS ESPÉCIES'!S51="", "", 'DADOS ESPÉCIES'!S51) -> CM
... D34: 9.5 | E34: =IF('DADOS ESPÉCIES'!D39="", "", 'DADOS ESPÉCIES'!D39) -> RC | F34: 19.5 | G34: =IF('DADOS ESPÉCIES'!D59="", "", 'DADOS ESPÉCIES'!D59) -> CD | H34: 9.5 | I34: =IF('DADOS ESPÉCIES'!I39="", "", 'DADOS ESPÉCIES'!I39) -> CM | J34: 19.5 | K34: =IF('DADOS ESPÉCIES'!I59="", "", 'DADOS ESPÉCIES'!I59) -> CD | L34: 9.5 | M34: =IF('DADOS ESPÉCIES'!N39="", "", 'DADOS ESPÉCIES'!N39) -> CD | N34: 19.5 | O34: =IF('DADOS ESPÉCIES'!N59="", "", 'DADOS ESPÉCIES'!N59) -> RC | P34: 9.5 | Q34: =IF('DADOS ESPÉCIES'!S39="", "", 'DADOS ESPÉCIES'!S39) -> CD | R34: 19.5 | S34: =IF('DADOS ESPÉCIES'!S59="", "", 'DADOS ESPÉCIES'!S59) -> CM
G35: A | I35: B | K35: C | M35: D | O35: Média do Segmento
B36: # de CD com doença: | G36: 0 | I36: 0 | K36: 0 | M36: 0 | O36: =AVERAGE(G36:N36) -> 0 | Q36: copiar da planilha de campo
B37: # de CD com branqueamento: | G37: 0 | I37: 0 | K37: 0 | M37: 0 | O37: =AVERAGE(G37:N37) -> 0 | Q37: copiar da planilha de campo
B38: % de CD com doença: | G38: =G36/C55 -> 0 | I38: =I36/E55 -> 0 | K38: =K36/G55 -> 0 | M38: =M36/I55 -> 0 | O38: =(G38+I38+K38+M38)/4 -> 0
B39: % de CD com branqueamento: | G39: =G37/C55 -> 0 | I39: =I37/E55 -> 0 | K39: =K37/G55 -> 0 | M39: =M37/I55 -> 0 | O39: =(G39+I39+K39+M39)/4 -> 0
B40: % of CRM: | G40: =C57/40 -> 0.025 | I40: =E57/40 -> 0.025 | K40: =G57/40 -> 0 | M40: =I57/40 -> 0 | O40: =(G40+I40+K40+M40)/4 -> 0.0125
B42: Se a média de CRM > 10%, a causa primária é:
B44: Comentários:
B47: Reef Check Brasil Sumário de Dados
B49: Total A | D49: Total B | F49: Total C | H49: Total D | J49: Grande total | M49: Média | N49: Média % por segmento | P49: DP | Q49: % A | R49: % B | S49: % C | T49: % D
B50: ACA | C50: =COUNTIF(E15:E34:G15:G34,"ACA") -> 0 | D50: ACA | E50: =COUNTIF(I15:I34:K15:K34,"ACA") -> 0 | F50: ACA | G50: =COUNTIF(M15:M34:O15:O34,"ACA") -> 0 | H50: ACA | I50: =COUNTIF(Q15:Q34:S15:S34,"ACA") -> 0 | J50: ACA | K50: =SUM(C50:E50:G50:I50) -> 0
B51: ACI | C51: =COUNTIF(E15:E34:G15:G34,"ACI") -> 6 | D51: ACI | E51: =COUNTIF(I15:I34:K15:K34,"ACI") -> 0 | F51: ACI | G51: =COUNTIF(M15:M34:O15:O34,"ACI") -> 0 | H51: ACI | I51: =COUNTIF(Q15:Q34:S15:S34,"ACI") -> 0 | J51: ACI | K51: =SUM(C51:E51:G51:I51) -> 6 | L51: ACA | M51: =AVERAGE(C50:E50:G50:I50) -> 0 | N51: =AVERAGE(Q51:R51:S51:T51) -> 0 | P51: =STDEV(Q51:R51:S51:T51) -> 0 | Q51: =C50/40 -> 0 | R51: =E50/40 -> 0 | S51: =G50/40 -> 0 | T51: =I50/40 -> 0
B52: AF | C52: =COUNTIF(E15:E34:G15:G34,"AF") -> 2 | D52: AF | E52: =COUNTIF(I15:I34:K15:K34,"AF") -> 2 | F52: AF | G52: =COUNTIF(M15:M34:O15:O34,"AF") -> 2 | H52: AF | I52: =COUNTIF(Q15:Q34:S15:S34,"AF") -> 2 | J52: AF | K52: =SUM(C52:E52:G52:I52) -> 8 | L52: ACI | M52: =AVERAGE(C51:E51:G51:I51) -> 1.5 | N52: =AVERAGE(Q52:R52:S52:T52) -> 0.0375 | P52: =STDEV(Q52:R52:S52:T52) -> 0.075 | Q52: =C51/40 -> 0.15 | R52: =E51/40 -> 0 | S52: =G51/40 -> 0 | T52: =I51/40 -> 0
B53: TURF | C53: =COUNTIF(E15:E34:G15:G34,"TURF") -> 0 | D53: TURF | E53: =COUNTIF(I15:I34:K15:K34,"TURF") -> 0 | F53: TURF | G53: =COUNTIF(M15:M34:O15:O34,"TURF") -> 0 | H53: TURF | I53: =COUNTIF(Q15:Q34:S15:S34,"TURF") -> 0 | J53: TURF | K53: =SUM(C53:E53:G53:I53) -> 0 | L53: AF | M53: =AVERAGE(C52:E52:G52:I52) -> 2 | N53: =AVERAGE(Q53:R53:S53:T53) -> 0.05 | P53: =STDEV(Q53:R53:S53:T53) -> 0 | Q53: =C52/40 -> 0.05 | R53: =E52/40 -> 0.05 | S53: =G52/40 -> 0.05 | T53: =I52/40 -> 0.05
B54: NIA | C54: =COUNTIF(E15:E34:G15:G34,"NIA") -> 0 | D54: NIA | E54: =COUNTIF(I15:I34:K15:K34,"NIA") -> 0 | F54: NIA | G54: =COUNTIF(M15:M34:O15:O34,"NIA") -> 0 | H54: NIA | I54: =COUNTIF(Q15:Q34:S15:S34,"NIA") -> 0 | J54: NIA | K54: =SUM(C54:E54:G54:I54) -> 0 | L54: TURF | M54: =AVERAGE(C53:E53:G53:I53) -> 0 | N54: =AVERAGE(Q54:R54:S54:T54) -> 0 | P54: =STDEV(Q54:R54:S54:T54) -> 0 | Q54: =C53/40 -> 0 | R54: =E53/40 -> 0 | S54: =G53/40 -> 0 | T54: =I53/40 -> 0
B55: CD | C55: =COUNTIF(E15:E34:G15:G34,"CD") -> 8 | D55: CD | E55: =COUNTIF(I15:I34:K15:K34,"CD") -> 14 | F55: CD | G55: =COUNTIF(M15:M34:O15:O34,"CD") -> 23 | H55: CD | I55: =COUNTIF(Q15:Q34:S15:S34,"CD") -> 15 | J55: CD | K55: =SUM(C55:E55:G55:I55) -> 60 | L55: NIA | M55: =AVERAGE(C54:E54:G54:I54) -> 0 | N55: =AVERAGE(Q55:R55:S55:T55) -> 0 | P55: =STDEV(Q55:R55:S55:T55) -> 0 | Q55: =C54/40 -> 0 | R55: =E54/40 -> 0 | S55: =G54/40 -> 0 | T55: =I54/40 -> 0
B56: CM | C56: =COUNTIF(E15:E34:G15:G34,"CM") -> 6 | D56: CM | E56: =COUNTIF(I15:I34:K15:K34,"CM") -> 15 | F56: CM | G56: =COUNTIF(M15:M34:O15:O34,"CM") -> 8 | H56: CM | I56: =COUNTIF(Q15:Q34:S15:S34,"CM") -> 12 | J56: CM | K56: =SUM(C56:E56:G56:I56) -> 41 | L56: CD | M56: =AVERAGE(C55:E55:G55:I55) -> 15 | N56: =AVERAGE(Q56:R56:S56:T56) -> 0.375 | P56: =STDEV(Q56:R56:S56:T56) -> 0.15411035 | Q56: =C55/40 -> 0.2 | R56: =E55/40 -> 0.35 | S56: =G55/40 -> 0.575 | T56: =I55/40 -> 0.375
B57: CRM | C57: =COUNTIF(E15:E34:G15:G34,"CRM") -> 1 | D57: CRM | E57: =COUNTIF(I15:I34:K15:K34,"CRM") -> 1 | F57: CRM | G57: =COUNTIF(M15:M34:O15:O34,"CRM") -> 0 | H57: CRM | I57: =COUNTIF(Q15:Q34:S15:S34,"CRM") -> 0 | J57: CRM | K57: =SUM(C57:E57:G57:I57) -> 2 | L57: CM | M57: =AVERAGE(C56:E56:G56:I56) -> 10.25 | N57: =AVERAGE(Q57:R57:S57:T57) -> 0.25625 | P57: =STDEV(Q57:R57:S57:T57) -> 0.10077822 | Q57: =C56/40 -> 0.15 | R57: =E56/40 -> 0.375 | S57: =G56/40 -> 0.2 | T57: =I56/40 -> 0.3
...

Sheet GRÁFICOS
B2: COMPLETE O TÍTULO DOS GRÁFICOS ONDE ESTÁ INDICADO A AZUL. PARA ALTERAR O TEXTO PARA PRETO, SELECIONE O TEXTO, CLIQUE NA OPÇÃO COR DE FONTE NA BARRA DE FERRAMENTAS FORMATAR E SELECIONE PRETO.
F4: Gráficos do Reef Check Brasil
B5: Dados do Reef Check Brasil
B8: Classes substrato | C8: Média % por segmento | D8: EP
B9: ACA | C9: =SUMÁRIO!N51 -> 0 | D9: =SUM(SUMÁRIO!P51/SQRT(4)) -> 0
B10: ACI | C10: =SUMÁRIO!N52 -> 0.0375 | D10: =SUM(SUMÁRIO!P52/SQRT(4)) -> 0.0375
B11: AF | C11: =SUMÁRIO!N53 -> 0.05 | D11: =SUM(SUMÁRIO!P53/SQRT(4)) -> 0
B12: TURF | C12: =SUMÁRIO!N54 -> 0 | D12: =SUM(SUMÁRIO!P54/SQRT(4)) -> 0
B13: NIA | C13: =SUMÁRIO!N55 -> 0 | D13: =SUM(SUMÁRIO!P55/SQRT(4)) -> 0
B14: CM | C14: =SUMÁRIO!N57 -> 0.25625 | D14: =SUM(SUMÁRIO!P57/SQRT(4)) -> 0.050389111
B15: CD | C15: =SUMÁRIO!N56 -> 0.375 | D15: =SUM(SUMÁRIO!P56/SQRT(4)) -> 0.077055175
B16: CRM | C16: =SUMÁRIO!N58 -> 0.0125 | D16: =SUM(SUMÁRIO!P58/SQRT(4)) -> 0.0072168784
B17: SP | C17: =SUMÁRIO!N63 -> 0 | D17: =SUM(SUMÁRIO!P63/SQRT(4)) -> 0
B18: OT | C18: =SUMÁRIO!N64 -> 0 | D18: =SUM(SUMÁRIO!P64/SQRT(4)) -> 0
B19: AR | C19: =SUMÁRIO!N61 -> 0 | D19: =SUM(SUMÁRIO!P61/SQRT(4)) -> 0
B20: AG | C20: =SUMÁRIO!N62 -> 0 | D20: =SUM(SUMÁRIO!P62/SQRT(4)) -> 0
B21: CC | C21: =SUMÁRIO!N60 -> 0 | D21: =SUM(SUMÁRIO!P60/SQRT(4)) -> 0
B22: RC | C22: =SUMÁRIO!N59 -> 0.26875 | D22: =SUM(SUMÁRIO!P59/SQRT(4)) -> 0.05625
B24: Conferir o Total = 100% | C24: =SUM(C9:C22) -> 1
B27: Cobertura viva de recife | C27: Média % por segmento | D27: EP
B28: CD | C28: =C15 -> 0.375 | D28: =D15 -> 0.077055175
B29: CM | C29: =C14 -> 0.25625 | D29: =D14 -> 0.050389111
B30: ACA | C30: =C9 -> 0 | D30: =D9 -> 0
B31: ACI | C31: =C10 -> 0.0375 | D31: =D10 -> 0.0375
B32: AF | C32: =C11 -> 0.05 | D32: =D11 -> 0
B33: TURF | C33: =C12 -> 0 | D33: =D12 -> 0
B34: NIA | C34: =C13 -> 0 | D34: =D13 -> 0
B35: SP | C35: =C17 -> 0 | D35: =D17 -> 0
B36: OT | C36: =C18 -> 0 | D36: =D18 -> 0
B39: Cobertura não viva de recife | C39: Média % por segmento | D39: EP
B40: CRM | C40: =C16 -> 0.0125 | D40: =D16 -> 0.0072168784
B41: AR | C41: =C19 -> 0 | D41: =D19 -> 0
B42: AG | C42: =C20 -> 0 | D42: =D20 -> 0
B43: CC | C43: =C21 -> 0 | D43: =D21 -> 0
B44: RC | C44: =C22 -> 0.26875 | D44: =D22 -> 0.05625

Sheet DADOS ESPÉCIES
C2: PREENCHA OS ESPAÇOS EM BRANCO | AD2: novo registro
I3: Algas | AD3: não identificada | AE3: alga calcária articulada | AF3: ACA
C4: Em caso de ser registrada uma espécie não descrita aqui, selecione como "novo registro" e adicione o nome em Observações. | J4: alga calcária articulada | K4: alga calcária articulada, Amphiroa sp, Jania sp, Halimeda sp, ACA+cianofícia | O4: Coral duro | P4: Mussismilia braziliensis | S4: Coral mole | AD4: sem espécie | AE4: alga calcária incrustante | AF4: ACI
C5: Em caso de identificar apenas a classe do indicador, preencha a coluna Espécie como "não identificada". | P5: Mussismilia harttii | S5: Palythoa caribaeorum, Palythoa grandiflora | U5: Ouriço comum Echinometra lucunter | AD5: Agaricia fragilis | AE5: alga folhosa | AF5: AF
N6: Escleractíneos | O6: Agaricia fragilis | P6: Mussismilia hispida | S6: Zoanthus pulchellus, Zoanthus sociatus | U6: Ouriço diadema Diadema antillarum | AD6: Agaricia humilis | AE6: algas turf | AF6: TURF
C7: Classes indicadores substrato | I7: alga calcária incrustante | K7: alga calcária incrustante | O7: Agaricia humilis | P7: Mussismilia hispida tenuisepta | S7: Zoanthus solander, Zoanthus sp | U7: Ouriço satélite Eucidaris tribuloides | AD7: Agaricia sp | AE7: alga indicadora de nutriente | AF7: NIA
C8: ACA | D8: alga calcária articulada | G8: Saúde (corais) | O8: Agaricia sp | U8: Ouriço branco Tripneustes ventricosus | AD8: alga calcária articulada | AE8: coral mole | AF8: CM
C9: ACI | D9: alga calcária incrustante | E9: SP | F9: esponja | G9: Branqueada | J9: alga folhosa | K9: Caulerpa sp, Dictyopteris sp, Dictyota sp, Padina sp, Sargassum sp | P9: Porites astreoides | S9: Outros | U9: Ouriço roxo Lytechinus sp | AD9: ACA + cianofícias | AE9: coral duro | AF9: CD
C10: AF | D10: alga folhosa | E10: OT | F10: outros | G10: Branqueada e doente | O10: Favia gravida | P10: Porites branneri | R10: Anêmona | S10: Bellactis ilkalyseae, Condylactis gigantea | AD10: alga calcária incrustante | AE10: coral recém morto | AF10: CRM
C11: TURF | D11: algas turf | G11: Doente | O11: Favia leptophylla | P11: Porites sp | U11: Octocoral Carijoa riisei, Neospongodes atlantica | AD11: alga filamentosa | AE11: esponja | AF11: SP
C12: NIA | D12: alga indicadora de nutriente | E12: AR | F12: areia | G12: Pálida e doente | J12: algas turf | K12: Tapete multiespecífico algas calcárias articuladas (ACA)/folhosas (turf AF)/filamentosas (turf AFil) | M12: Hidrocorais | N12: Millepora alcicornis | R12: Ascídia | S12: não identificada | AD12: alga folhosa | AE12: outros | AF12: OT
E13: AG | F13: argila | G13: Pálida | N13: Millepora braziliensis | O13: Madracis decactis | P13: Scolymia wellsi | U13: Polvo Octopus insularis, Octopus vulgaris | AD13: algas turf | AE13: areia | AF13: AR
C14: CM | D14: coral mole | E14: CC | F14: cascalho | G14: Sadia | N14: Millepora nitida | O14: Meandrina braziliensis | P14: Siderastrea sp | R14: Gorgônia | S14: Muriceopsis sulphurea, Muriceopsis sp, Phyllogorgia dilatata, Plexaurella dichotoma, Plexaurella grandiflora, Pleuxaurella regia, Pleuxaurella sp | AD14: Amphiroa sp | AE14: argila | AF14: AG
C15: CD | D15: coral duro | E15: RC | F15: rocha | G15: Sem registro | I15: alga indicadora de nutriente | K15: alga filamentosa, cianobactérias, Chaetomorpha sp, Ulva sp | N15: Millepora sp | O15: Montastraea cavernosa | P15: Stephanocoenia michelini | U15: Esponja não identificada | AD15: Anêmona | AE15: cascalho | AF15: CC
C16: CRM | D16: coral recém morto | N16: Stylaster roseus | AD16: Ascídia | AE16: rocha | AF16: RC
AD17: Carijoa riisei
C18: SEGMENTO A | H18: SEGMENTO B | M18: SEGMENTO C | R18: SEGMENTO D | AD18: Caulerpa sp
C19: Distância | D19: Abreviatura | E19: Classe indicador | F19: Espécie | G19: Saúde | H19: Distância | I19: Abreviatura | J19: Classe indicador | K19: Espécie | L19: Saúde | M19: Distância | N19: Abreviatura | O19: Classe indicador | P19: Espécie | Q19: Saúde | R19: Distância | S19: Abreviatura | T19: Classe indicador | U19: Espécie | V19: Saúde | AD19: Chaetomorpha sp
C20: 0 | D20: =IFERROR(VLOOKUP(E20,$AE$3:$AF$17,2,FALSE),"") -> CM | E20: coral mole | F20: palythoa caribaeorum | G20: sadia | H20: 0 | I20: =IFERROR(VLOOKUP(J20,$AE$3:$AF$17,2,FALSE),"") -> CM | J20: coral mole | K20: palythoa caribaeorum | L20: sadia | M20: 0 | N20: =IFERROR(VLOOKUP(O20,$AE$3:$AF$17,2,FALSE),"") -> CM | O20: coral mole | P20: muriceopsis sulphurea | Q20: sadia | R20: 0 | S20: =IFERROR(VLOOKUP(T20,$AE$3:$AF$17,2,FALSE),"") -> CD | T20: coral duro | U20: millepora nitida | V20: sadia | AD20: Cianobacteria
C21: 0.5 | D21: =IFERROR(VLOOKUP(E21,$AE$3:$AF$17,2,FALSE),"") -> RC | E21: rocha | H21: 0.5 | I21: =IFERROR(VLOOKUP(J21,$AE$3:$AF$17,2,FALSE),"") -> CM | J21: coral mole | K21: palythoa caribaeorum | L21: sadia | M21: 0.5 | N21: =IFERROR(VLOOKUP(O21,$AE$3:$AF$17,2,FALSE),"") -> CM | O21: coral mole | P21: muriceopsis sulphurea | Q21: sadia | R21: 0.5 | S21: =IFERROR(VLOOKUP(T21,$AE$3:$AF$17,2,FALSE),"") -> RC | T21: rocha | AD21: Condylactis gigantea
C22: 1 | D22: =IFERROR(VLOOKUP(E22,$AE$3:$AF$17,2,FALSE),"") -> CM | E22: coral mole | F22: muriceopsis sulphurea | G22: sadia | H22: 1 | I22: =IFERROR(VLOOKUP(J22,$AE$3:$AF$17,2,FALSE),"") -> CM | J22: coral mole | K22: muriceopsis sulphurea | L22: sadia | M22: 1 | N22: =IFERROR(VLOOKUP(O22,$AE$3:$AF$17,2,FALSE),"") -> CD | O22: coral duro | P22: millepora nitida | Q22: sadia | R22: 1 | S22: =IFERROR(VLOOKUP(T22,$AE$3:$AF$17,2,FALSE),"") -> CD | T22: coral duro | U22: favia gravida | V22: sadia | AD22: Diadema antillarum
C23: 1.5 | D23: =IFERROR(VLOOKUP(E23,$AE$3:$AF$17,2,FALSE),"") -> RC | E23: rocha | H23: 1.5 | I23: =IFERROR(VLOOKUP(J23,$AE$3:$AF$17,2,FALSE),"") -> CRM | J23: coral recém morto | K23: siderastrea sp | M23: 1.5 | N23: =IFERROR(VLOOKUP(O23,$AE$3:$AF$17,2,FALSE),"") -> RC | O23: rocha | R23: 1.5 | S23: =IFERROR(VLOOKUP(T23,$AE$3:$AF$17,2,FALSE),"") -> RC | T23: rocha | AD23: Dictyopteris sp
C24: 2 | D24: =IFERROR(VLOOKUP(E24,$AE$3:$AF$17,2,FALSE),"") -> ACI | E24: alga calcária incrustante | F24: não identificada | H24: 2 | I24: =IFERROR(VLOOKUP(J24,$AE$3:$AF$17,2,FALSE),"") -> CD | J24: coral duro | K24: millepora nitida | L24: sadia | M24: 2 | N24: =IFERROR(VLOOKUP(O24,$AE$3:$AF$17,2,FALSE),"") -> RC | O24: rocha | R24: 2 | S24: =IFERROR(VLOOKUP(T24,$AE$3:$AF$17,2,FALSE),"") -> RC | T24: rocha | AD24: Dictyota sp
C25: 2.5 | D25: =IFERROR(VLOOKUP(E25,$AE$3:$AF$17,2,FALSE),"") -> CM | E25: coral mole | F25: muriceopsis sulphurea | G25: sadia | H25: 2.5 | I25: =IFERROR(VLOOKUP(J25,$AE$3:$AF$17,2,FALSE),"") -> CM | J25: coral mole | K25: muriceopsis sulphurea | L25: sadia | M25: 2.5 | N25: =IFERROR(VLOOKUP(O25,$AE$3:$AF$17,2,FALSE),"") -> CD | O25: coral duro | P25: millepora nitida | Q25: sadia | R25: 2.5 | S25: =IFERROR(VLOOKUP(T25,$AE$3:$AF$17,2,FALSE),"") -> CD | T25: coral duro | U25: millepora nitida | V25: sadia | AD25: Echinometra lucunter
C26: 3 | D26: =IFERROR(VLOOKUP(E26,$AE$3:$AF$17,2,FALSE),"") -> CD | E26: coral duro | F26: siderastrea sp | G26: sadia | H26: 3 | I26: =IFERROR(VLOOKUP(J26,$AE$3:$AF$17,2,FALSE),"") -> CM | J26: coral mole | K26: muriceopsis sulphurea | L26: sadia | M26: 3 | N26: =IFERROR(VLOOKUP(O26,$AE$3:$AF$17,2,FALSE),"") -> RC | O26: rocha | R26: 3 | S26: =IFERROR(VLOOKUP(T26,$AE$3:$AF$17,2,FALSE),"") -> CM | T26: coral mole | U26: muriceopsis sulphurea | V26: sadia | AD26: Eucidaris tribuloides
C27: 3.5 | D27: =IFERROR(VLOOKUP(E27,$AE$3:$AF$17,2,FALSE),"") -> ACI | E27: alga calcária incrustante | F27: não identificada | H27: 3.5 | I27: =IFERROR(VLOOKUP(J27,$AE$3:$AF$17,2,FALSE),"") -> CD | J27: coral duro | K27: favia gravida | L27: sadia | M27: 3.5 | N27: =IFERROR(VLOOKUP(O27,$AE$3:$AF$17,2,FALSE),"") -> CM | O27: coral mole | P27: muriceopsis sulphurea | Q27: sadia | R27: 3.5 | S27: =IFERROR(VLOOKUP(T27,$AE$3:$AF$17,2,FALSE),"") -> AF | T27: alga folhosa | U27: não identificada | AD27: Favia gravida
C28: 4 | D28: =IFERROR(VLOOKUP(E28,$AE$3:$AF$17,2,FALSE),"") -> RC | E28: rocha | H28: 4 | I28: =IFERROR(VLOOKUP(J28,$AE$3:$AF$17,2,FALSE),"") -> RC | J28: rocha | M28: 4 | N28: =IFERROR(VLOOKUP(O28,$AE$3:$AF$17,2,FALSE),"") -> CM | O28: coral mole | P28: muriceopsis sulphurea | Q28: sadia | R28: 4 | S28: =IFERROR(VLOOKUP(T28,$AE$3:$AF$17,2,FALSE),"") -> RC | T28: rocha | AD28: Favia leptophylla
C29: 4.5 | D29: =IFERROR(VLOOKUP(E29,$AE$3:$AF$17,2,FALSE),"") -> ACI | E29: alga calcária incrustante | F29: não identificada | H29: 4.5 | I29: =IFERROR(VLOOKUP(J29,$AE$3:$AF$17,2,FALSE),"") -> CD | J29: coral duro | K29: siderastrea sp | L29: sadia | M29: 4.5 | N29: =IFERROR(VLOOKUP(O29,$AE$3:$AF$17,2,FALSE),"") -> CD | O29: coral duro | P29: mussismilia hispida | Q29: sadia | R29: 4.5 | S29: =IFERROR(VLOOKUP(T29,$AE$3:$AF$17,2,FALSE),"") -> RC | T29: rocha | AD29: Gorgônia
C30: 5 | D30: =IFERROR(VLOOKUP(E30,$AE$3:$AF$17,2,FALSE),"") -> RC | E30: rocha | H30: 5 | I30: =IFERROR(VLOOKUP(J30,$AE$3:$AF$17,2,FALSE),"") -> RC | J30: rocha | M30: 5 | N30: =IFERROR(VLOOKUP(O30,$AE$3:$AF$17,2,FALSE),"") -> CD | O30: coral duro | P30: millepora nitida | Q30: sadia | R30: 5 | S30: =IFERROR(VLOOKUP(T30,$AE$3:$AF$17,2,FALSE),"") -> CD | T30: coral duro | U30: mussismilia harttii | V30: sadia | AD30: Halimeda sp
C31: 5.5 | D31: =IFERROR(VLOOKUP(E31,$AE$3:$AF$17,2,FALSE),"") -> RC | E31: rocha | H31: 5.5 | I31: =IFERROR(VLOOKUP(J31,$AE$3:$AF$17,2,FALSE),"") -> AF | J31: alga folhosa | K31: não identificada | M31: 5.5 | N31: =IFERROR(VLOOKUP(O31,$AE$3:$AF$17,2,FALSE),"") -> CM | O31: coral mole | P31: muriceopsis sulphurea | Q31: sadia | R31: 5.5 | S31: =IFERROR(VLOOKUP(T31,$AE$3:$AF$17,2,FALSE),"") -> CD | T31: coral duro | U31: mussismilia harttii | V31: sadia | AD31: Jania sp
C32: 6 | D32: =IFERROR(VLOOKUP(E32,$AE$3:$AF$17,2,FALSE),"") -> RC | E32: rocha | H32: 6 | I32: =IFERROR(VLOOKUP(J32,$AE$3:$AF$17,2,FALSE),"") -> CD | J32: coral duro | K32: siderastrea sp | L32: sadia | M32: 6 | N32: =IFERROR(VLOOKUP(O32,$AE$3:$AF$17,2,FALSE),"") -> RC | O32: rocha | R32: 6 | S32: =IFERROR(VLOOKUP(T32,$AE$3:$AF$17,2,FALSE),"") -> CD | T32: coral duro | U32: mussismilia harttii | V32: sadia | AD32: Lebrunia sp
C33: 6.5 | D33: =IFERROR(VLOOKUP(E33,$AE$3:$AF$17,2,FALSE),"") -> RC | E33: rocha | H33: 6.5 | I33: =IFERROR(VLOOKUP(J33,$AE$3:$AF$17,2,FALSE),"") -> CM | J33: coral mole | K33: muriceopsis sulphurea | L33: sadia | M33: 6.5 | N33: =IFERROR(VLOOKUP(O33,$AE$3:$AF$17,2,FALSE),"") -> CD | O33: coral duro | P33: porites astreoides | Q33: sadia | R33: 6.5 | S33: =IFERROR(VLOOKUP(T33,$AE$3:$AF$17,2,FALSE),"") -> RC | T33: rocha | AD33: Lytechinus sp
C34: 7 | D34: =IFERROR(VLOOKUP(E34,$AE$3:$AF$17,2,FALSE),"") -> CM | E34: coral mole | F34: muriceopsis sulphurea | G34: sadia | H34: 7 | I34: =IFERROR(VLOOKUP(J34,$AE$3:$AF$17,2,FALSE),"") -> CM | J34: coral mole | K34: muriceopsis sulphurea | L34: sadia | M34: 7 | N34: =IFERROR(VLOOKUP(O34,$AE$3:$AF$17,2,FALSE),"") -> CD | O34: coral duro | P34: millepora nitida | Q34: sadia | R34: 7 | S34: =IFERROR(VLOOKUP(T34,$AE$3:$AF$17,2,FALSE),"") -> CD | T34: coral duro | U34: millepora nitida | V34: sadia | AD34: Madracis decactis
C35: 7.5 | D35: =IFERROR(VLOOKUP(E35,$AE$3:$AF$17,2,FALSE),"") -> CD | E35: coral duro | F35: agaricia humilis | G35: sadia | H35: 7.5 | I35: =IFERROR(VLOOKUP(J35,$AE$3:$AF$17,2,FALSE),"") -> CM | J35: coral mole | K35: muriceopsis sulphurea | L35: sadia | M35: 7.5 | N35: =IFERROR(VLOOKUP(O35,$AE$3:$AF$17,2,FALSE),"") -> CD | O35: coral duro | P35: millepora nitida | Q35: sadia | R35: 7.5 | S35: =IFERROR(VLOOKUP(T35,$AE$3:$AF$17,2,FALSE),"") -> RC | T35: rocha | AD35: Meandrina braziliensis
C36: 8 | D36: =IFERROR(VLOOKUP(E36,$AE$3:$AF$17,2,FALSE),"") -> CD | E36: coral duro | F36: siderastrea sp | G36: sadia | H36: 8 | I36: =IFERROR(VLOOKUP(J36,$AE$3:$AF$17,2,FALSE),"") -> CM | J36: coral mole | K36: muriceopsis sulphurea | L36: sadia | M36: 8 | N36: =IFERROR(VLOOKUP(O36,$AE$3:$AF$17,2,FALSE),"") -> CD | O36: coral duro | P36: siderastrea sp | Q36: sadia | R36: 8 | S36: =IFERROR(VLOOKUP(T36,$AE$3:$AF$17,2,FALSE),"") -> CD | T36: coral duro | U36: mussismilia harttii | V36: sadia | AD36: Millepora alcicornis
C37: 8.5 | D37: =IFERROR(VLOOKUP(E37,$AE$3:$AF$17,2,FALSE),"") -> RC | E37: rocha | H37: 8.5 | I37: =IFERROR(VLOOKUP(J37,$AE$3:$AF$17,2,FALSE),"") -> CM | J37: coral mole | K37: palythoa caribaeorum | L37: sadia | M37: 8.5 | N37: =IFERROR(VLOOKUP(O37,$AE$3:$AF$17,2,FALSE),"") -> CD | O37: coral duro | P37: millepora nitida | Q37: sadia | R37: 8.5 | S37: =IFERROR(VLOOKUP(T37,$AE$3:$AF$17,2,FALSE),"") -> CD | T37: coral duro | U37: porites astreoides | V37: sadia | AD37: Millepora braziliensis
C38: 9 | D38: =IFERROR(VLOOKUP(E38,$AE$3:$AF$17,2,FALSE),"") -> RC | E38: rocha | H38: 9 | I38: =IFERROR(VLOOKUP(J38,$AE$3:$AF$17,2,FALSE),"") -> CM | J38: coral mole | K38: palythoa caribaeorum | L38: sadia | M38: 9 | N38: =IFERROR(VLOOKUP(O38,$AE$3:$AF$17,2,FALSE),"") -> CD | O38: coral duro | P38: millepora nitida | Q38: sadia | R38: 9 | S38: =IFERROR(VLOOKUP(T38,$AE$3:$AF$17,2,FALSE),"") -> CM | T38: coral mole | U38: muriceopsis sulphurea | V38: sadia | AD38: Millepora nitida
C39: 9.5 | D39: =IFERROR(VLOOKUP(E39,$AE$3:$AF$17,2,FALSE),"") -> RC | E39: rocha | H39: 9.5 | I39: =IFERROR(VLOOKUP(J39,$AE$3:$AF$17,2,FALSE),"") -> CM | J39: coral mole | K39: palythoa caribaeorum | L39: sadia | M39: 9.5 | N39: =IFERROR(VLOOKUP(O39,$AE$3:$AF$17,2,FALSE),"") -> CD | O39: coral duro | P39: millepora nitida | Q39: sadia | R39: 9.5 | S39: =IFERROR(VLOOKUP(T39,$AE$3:$AF$17,2,FALSE),"") -> CD | T39: coral duro | U39: siderastrea sp | V39: sadia | AD39: Millepora sp
C40: 10 | D40: =IFERROR(VLOOKUP(E40,$AE$3:$AF$17,2,FALSE),"") -> RC | E40: rocha | H40: 10 | I40: =IFERROR(VLOOKUP(J40,$AE$3:$AF$17,2,FALSE),"") -> CD | J40: coral duro | K40: mussismilia braziliensis | L40: sadia | M40: 10 | N40: =IFERROR(VLOOKUP(O40,$AE$3:$AF$17,2,FALSE),"") -> CD | O40: coral duro | P40: mussismilia braziliensis | Q40: sadia | R40: 10 | S40: =IFERROR(VLOOKUP(T40,$AE$3:$AF$17,2,FALSE),"") -> AF | T40: alga folhosa | U40: não identificada | AD40: Montastraea cavernosa
C41: 10.5 | D41: =IFERROR(VLOOKUP(E41,$AE$3:$AF$17,2,FALSE),"") -> CD | E41: coral duro | F41: millepora nitida | G41: sadia | H41: 10.5 | I41: =IFERROR(VLOOKUP(J41,$AE$3:$AF$17,2,FALSE),"") -> CD | J41: coral duro | K41: mussismilia braziliensis | L41: sadia | M41: 10.5 | N41: =IFERROR(VLOOKUP(O41,$AE$3:$AF$17,2,FALSE),"") -> CD | O41: coral duro | P41: millepora nitida | Q41: sadia | R41: 10.5 | S41: =IFERROR(VLOOKUP(T41,$AE$3:$AF$17,2,FALSE),"") -> CM | T41: coral mole | U41: muriceopsis sulphurea | V41: sadia | AD41: Muriceopsis sulphurea
...
